Workbook

Sheet Planilha1
A1: ORIGEM | B1: TIPO | C1: NUMDOC | D1: CODCLIFOR | E1: SERIE | F1: TIPDOC | G1: DATATU | H1: CODCTA | I1: CODFIL | J1: CODUNN | K1: UNIDADE | L1: CODCGA | M1: GASTO | N1: CODCUS | O1: DESCRI | P1: SINTET | Q1: SINTETICA | R1: ANALIT | S1: ANALITICA | T1: RECDES | U1: MES | V1: TRIMESTRE | W1: ANO | X1: VLRIMP_REAL | Y1: VLRIMP | Z1: VLRINI | AA1: VLRAJUS | AB1: VLRREM | AC1: VLRAJUS2 | AD1: VLRREA | AE1: VLRFOR | AF1: OBSERVACAO | AG1: Placa | AH1: FONTE_DOC | AI1: COD_PACOTE | AJ1: PACOTE | AK1: CODGER | AL1: CODGRU | AM1: SITUAC | AN1: USUATU | AO1: NUMDUP | AP1: FILDUP | AQ1: DATFIS
A2: FIN | B2: REALIZADO | C2: 000001794ME0057 | D2: 119473 | E2: 1 | F2: FIN | G2: 2026-03-26 09:29:00.000 | H2: NULL | I2: 27 | J2: 21 | K2: TRANSFERÊNCIA URBANA - EMPURRADA | L2: 112 | M2: OPERALOG AMAZÔNIA - CAMAÇARI | N2: 35 | O2: OPERACIONAL | P2: 149 | Q2: FINANCIAMENTOS DE VEÍCULOS PESADOS - VP | R2: 61 | S2: C.D.C. - VP | T2: D | U2: 4 | V2: 2 | W2: 2026 | X2: 0 | Y2: 0 | Z2: 0.00000000000 | AA2: 0.00 | AB2: 0 | AC2: 0.000000 | AD2: -10817.54 | AE2: 0.00 | AF2: 2272 | AG2: =_xlfn.XLOOKUP(AF2,Planilha2!B:B,Planilha2!A:A,0,0) -> QYZ-3E44 | AH2: FIN | AI2: 3 | AJ2: OPERACIONAL | AK2: 14 | AL2: 3 | AM2: L | AN2: ISABELA.SILVA | AO2: NULL | AP2: NULL | AQ2: 2021-08-19 00:00:00.000
A3: FIN | B3: REALIZADO | C3: 000002089ME0046 | D3: 119473 | E3: 1 | F3: FIN | G3: 2026-05-26 16:39:00.000 | H3: NULL | I3: 19 | J3: 21 | K3: TRANSFERÊNCIA URBANA - EMPURRADA | L3: 112 | M3: OPERALOG AMAZÔNIA - CAMAÇARI | N3: 35 | O3: OPERACIONAL | P3: 149 | Q3: FINANCIAMENTOS DE VEÍCULOS PESADOS - VP | R3: 61 | S3: C.D.C. - VP | T3: D | U3: 6 | V3: 2 | W3: 2026 | X3: 0 | Y3: 0 | Z3: 0.00000000000 | AA3: 0.00 | AB3: 0 | AC3: 0.000000 | AD3: -25085.47 | AE3: 0.00 | AF3: 2524 | AG3: =_xlfn.XLOOKUP(AF3,Planilha2!B:B,Planilha2!A:A,0,0) -> RPG-5D53 | AH3: FIN | AI3: 3 | AJ3: OPERACIONAL | AK3: 14 | AL3: 3 | AM3: L | AN3: ISABELA.SILVA | AO3: NULL | AP3: NULL | AQ3: 2022-07-28 00:00:00.000
A4: FIN | B4: REALIZADO | C4: 000001849ME0054 | D4: 119473 | E4: 1 | F4: FIN | G4: 2026-03-26 09:00:00.000 | H4: NULL | I4: 27 | J4: 21 | K4: TRANSFERÊNCIA URBANA - EMPURRADA | L4: 112 | M4: OPERALOG AMAZÔNIA - CAMAÇARI | N4: 35 | O4: OPERACIONAL | P4: 149 | Q4: FINANCIAMENTOS DE VEÍCULOS PESADOS - VP | R4: 61 | S4: C.D.C. - VP | T4: D | U4: 4 | V4: 2 | W4: 2026 | X4: 0 | Y4: 0 | Z4: 0.00000000000 | AA4: 0.00 | AB4: 0 | AC4: 0.000000 | AD4: -6447.322 | AE4: 0.00 | AF4: 2037 | AG4: =_xlfn.XLOOKUP(AF4,Planilha2!B:B,Planilha2!A:A,0,0) -> RZF-8B28 | AH4: FIN | AI4: 3 | AJ4: OPERACIONAL | AK4: 14 | AL4: 3 | AM4: L | AN4: ISABELA.SILVA | AO4: NULL | AP4: NULL | AQ4: 2021-11-01 00:00:00.000
A5: FIN | B5: REALIZADO | C5: 000002089ME0048 | D5: 119473 | E5: 1 | F5: FIN | G5: 2026-07-23 17:14:00.000 | H5: NULL | I5: 19 | J5: 21 | K5: TRANSFERÊNCIA URBANA - EMPURRADA | L5: 112 | M5: OPERALOG AMAZÔNIA - CAMAÇARI | N5: 35 | O5: OPERACIONAL | P5: 149 | Q5: FINANCIAMENTOS DE VEÍCULOS PESADOS - VP | R5: 61 | S5: C.D.C. - VP | T5: D | U5: 8 | V5: 3 | W5: 2026 | X5: 0 | Y5: 0 | Z5: 0.00000000000 | AA5: 0.00 | AB5: 0 | AC5: 0.000000 | AD5: -25085.47 | AE5: 0.00 | AF5: 2524 | AG5: =_xlfn.XLOOKUP(AF5,Planilha2!B:B,Planilha2!A:A,0,0) -> RPG-5D53 | AH5: FIN | AI5: 3 | AJ5: OPERACIONAL | AK5: 14 | AL5: 3 | AM5: L | AN5: ISABELA.SILVA | AO5: NULL | AP5: NULL | AQ5: 2022-07-28 00:00:00.000
A6: FIN | B6: REALIZADO | C6: 000002089ME0046 | D6: 119473 | E6: 1 | F6: FIN | G6: 2026-05-26 16:39:00.000 | H6: NULL | I6: 19 | J6: 21 | K6: TRANSFERÊNCIA URBANA - EMPURRADA | L6: 112 | M6: OPERALOG AMAZÔNIA - CAMAÇARI | N6: 35 | O6: OPERACIONAL | P6: 149 | Q6: FINANCIAMENTOS DE VEÍCULOS PESADOS - VP | R6: 61 | S6: C.D.C. - VP | T6: D | U6: 6 | V6: 2 | W6: 2026 | X6: 0 | Y6: 0 | Z6: 0.00000000000 | AA6: 0.00 | AB6: 0 | AC6: 0.000000 | AD6: -25085.47 | AE6: 0.00 | AF6: 2528 | AG6: =_xlfn.XLOOKUP(AF6,Planilha2!B:B,Planilha2!A:A,0,0) -> RPG-7A20 | AH6: FIN | AI6: 3 | AJ6: OPERACIONAL | AK6: 14 | AL6: 3 | AM6: L | AN6: ISABELA.SILVA | AO6: NULL | AP6: NULL | AQ6: 2022-07-28 00:00:00.000
A7: FIN | B7: REALIZADO | C7: 000001822ME0056 | D7: 119473 | E7: 1 | F7: FIN | G7: 2026-04-29 13:21:00.000 | H7: NULL | I7: 27 | J7: 21 | K7: TRANSFERÊNCIA URBANA - EMPURRADA | L7: 112 | M7: OPERALOG AMAZÔNIA - CAMAÇARI | N7: 35 | O7: OPERACIONAL | P7: 149 | Q7: FINANCIAMENTOS DE VEÍCULOS PESADOS - VP | R7: 61 | S7: C.D.C. - VP | T7: D | U7: 5 | V7: 2 | W7: 2026 | X7: 0 | Y7: 0 | Z7: 0.00000000000 | AA7: 0.00 | AB7: 0 | AC7: 0.000000 | AD7: -5896.428 | AE7: 0.00 | AF7: 2077 | AG7: =_xlfn.XLOOKUP(AF7,Planilha2!B:B,Planilha2!A:A,0,0) -> RZF-9F80 | AH7: FIN | AI7: 3 | AJ7: OPERACIONAL | AK7: 14 | AL7: 3 | AM7: L | AN7: ISABELA.SILVA | AO7: NULL | AP7: NULL | AQ7: 2021-09-14 00:00:00.000
A8: FIN | B8: REALIZADO | C8: 000002089ME0048 | D8: 119473 | E8: 1 | F8: FIN | G8: 2026-07-23 17:14:00.000 | H8: NULL | I8: 19 | J8: 21 | K8: TRANSFERÊNCIA URBANA - EMPURRADA | L8: 112 | M8: OPERALOG AMAZÔNIA - CAMAÇARI | N8: 35 | O8: OPERACIONAL | P8: 149 | Q8: FINANCIAMENTOS DE VEÍCULOS PESADOS - VP | R8: 61 | S8: C.D.C. - VP | T8: D | U8: 8 | V8: 3 | W8: 2026 | X8: 0 | Y8: 0 | Z8: 0.00000000000 | AA8: 0.00 | AB8: 0 | AC8: 0.000000 | AD8: -25085.47 | AE8: 0.00 | AF8: 2530 | AG8: =_xlfn.XLOOKUP(AF8,Planilha2!B:B,Planilha2!A:A,0,0) -> RPG-6H27 | AH8: FIN | AI8: 3 | AJ8: OPERACIONAL | AK8: 14 | AL8: 3 | AM8: L | AN8: ISABELA.SILVA | AO8: NULL | AP8: NULL | AQ8: 2022-07-28 00:00:00.000
A9: FIN | B9: REALIZADO | C9: 000001822ME0060 | D9: 119473 | E9: 1 | F9: FIN | G9: 2026-08-28 08:33:00.000 | H9: NULL | I9: 27 | J9: 21 | K9: TRANSFERÊNCIA URBANA - EMPURRADA | L9: 112 | M9: OPERALOG AMAZÔNIA - CAMAÇARI | N9: 35 | O9: OPERACIONAL | P9: 149 | Q9: FINANCIAMENTOS DE VEÍCULOS PESADOS - VP | R9: 61 | S9: C.D.C. - VP | T9: D | U9: 9 | V9: 3 | W9: 2026 | X9: 0 | Y9: 0 | Z9: 0.00000000000 | AA9: 0.00 | AB9: 0 | AC9: 0.000000 | AD9: -5896.428 | AE9: 0.00 | AF9: 2075 | AG9: =_xlfn.XLOOKUP(AF9,Planilha2!B:B,Planilha2!A:A,0,0) -> RZF-9F40 | AH9: FIN | AI9: 3 | AJ9: OPERACIONAL | AK9: 14 | AL9: 3 | AM9: L | AN9: ISABELA.SILVA | AO9: NULL | AP9: NULL | AQ9: 2021-09-14 00:00:00.000
A10: FIN | B10: REALIZADO | C10: 000001847ME0057 | D10: 119473 | E10: 1 | F10: FIN | G10: 2026-06-26 11:02:00.000 | H10: NULL | I10: 27 | J10: 21 | K10: TRANSFERÊNCIA URBANA - EMPURRADA | L10: 112 | M10: OPERALOG AMAZÔNIA - CAMAÇARI | N10: 35 | O10: OPERACIONAL | P10: 149 | Q10: FINANCIAMENTOS DE VEÍCULOS PESADOS - VP | R10: 61 | S10: C.D.C. - VP | T10: D | U10: 7 | V10: 3 | W10: 2026 | X10: 0 | Y10: 0 | Z10: 0.00000000000 | AA10: 0.00 | AB10: 0 | AC10: 0.000000 | AD10: -6447.322 | AE10: 0.00 | AF10: 2021 | AG10: =_xlfn.XLOOKUP(AF10,Planilha2!B:B,Planilha2!A:A,0,0) -> RZF-8E78 | AH10: FIN | AI10: 3 | AJ10: OPERACIONAL | AK10: 14 | AL10: 3 | AM10: L | AN10: ISABELA.SILVA | AO10: NULL | AP10: NULL | AQ10: 2021-11-08 00:00:00.000
A11: FIN | B11: REALIZADO | C11: 000001822ME0056 | D11: 119473 | E11: 1 | F11: FIN | G11: 2026-04-29 13:21:00.000 | H11: NULL | I11: 27 | J11: 21 | K11: TRANSFERÊNCIA URBANA - EMPURRADA | L11: 112 | M11: OPERALOG AMAZÔNIA - CAMAÇARI | N11: 35 | O11: OPERACIONAL | P11: 149 | Q11: FINANCIAMENTOS DE VEÍCULOS PESADOS - VP | R11: 61 | S11: C.D.C. - VP | T11: D | U11: 5 | V11: 2 | W11: 2026 | X11: 0 | Y11: 0 | Z11: 0.00000000000 | AA11: 0.00 | AB11: 0 | AC11: 0.000000 | AD11: -5896.428 | AE11: 0.00 | AF11: 2075 | AG11: =_xlfn.XLOOKUP(AF11,Planilha2!B:B,Planilha2!A:A,0,0) -> RZF-9F40 | AH11: FIN | AI11: 3 | AJ11: OPERACIONAL | AK11: 14 | AL11: 3 | AM11: L | AN11: ISABELA.SILVA | AO11: NULL | AP11: NULL | AQ11: 2021-09-14 00:00:00.000
A12: FIN | B12: REALIZADO | C12: 000001822ME0060 | D12: 119473 | E12: 1 | F12: FIN | G12: 2026-08-28 08:33:00.000 | H12: NULL | I12: 27 | J12: 21 | K12: TRANSFERÊNCIA URBANA - EMPURRADA | L12: 112 | M12: OPERALOG AMAZÔNIA - CAMAÇARI | N12: 35 | O12: OPERACIONAL | P12: 149 | Q12: FINANCIAMENTOS DE VEÍCULOS PESADOS - VP | R12: 61 | S12: C.D.C. - VP | T12: D | U12: 9 | V12: 3 | W12: 2026 | X12: 0 | Y12: 0 | Z12: 0.00000000000 | AA12: 0.00 | AB12: 0 | AC12: 0.000000 | AD12: -5896.428 | AE12: 0.00 | AF12: 2077 | AG12: =_xlfn.XLOOKUP(AF12,Planilha2!B:B,Planilha2!A:A,0,0) -> RZF-9F80 | AH12: FIN | AI12: 3 | AJ12: OPERACIONAL | AK12: 14 | AL12: 3 | AM12: L | AN12: ISABELA.SILVA | AO12: NULL | AP12: NULL | AQ12: 2021-09-14 00:00:00.000
A13: FIN | B13: REALIZADO | C13: 000001852ME0059 | D13: 119473 | E13: 1 | F13: FIN | G13: 2026-08-20 12:50:00.000 | H13: NULL | I13: 27 | J13: 21 | K13: TRANSFERÊNCIA URBANA - EMPURRADA | L13: 112 | M13: OPERALOG AMAZÔNIA - CAMAÇARI | N13: 35 | O13: OPERACIONAL | P13: 149 | Q13: FINANCIAMENTOS DE VEÍCULOS PESADOS - VP | R13: 61 | S13: C.D.C. - VP | T13: D | U13: 9 | V13: 3 | W13: 2026 | X13: 0 | Y13: 0 | Z13: 0.00000000000 | AA13: 0.00 | AB13: 0 | AC13: 0.000000 | AD13: -6447.322 | AE13: 0.00 | AF13: 2051 | AG13: =_xlfn.XLOOKUP(AF13,Planilha2!B:B,Planilha2!A:A,0,0) -> RZF-7H88 | AH13: FIN | AI13: 3 | AJ13: OPERACIONAL | AK13: 14 | AL13: 3 | AM13: L | AN13: ISABELA.SILVA | AO13: NULL | AP13: NULL | AQ13: 2021-11-04 00:00:00.000
... A42: FIN | B42: REALIZADO | C42: 000001822ME0057 | D42: 119473 | E42: 1 | F42: FIN | G42: 2026-05-26 17:15:00.000 | H42: NULL | I42: 27 | J42: 21 | K42: TRANSFERÊNCIA URBANA - EMPURRADA | L42: 112 | M42: OPERALOG AMAZÔNIA - CAMAÇARI | N42: 35 | O42: OPERACIONAL | P42: 149 | Q42: FINANCIAMENTOS DE VEÍCULOS PESADOS - VP | R42: 61 | S42: C.D.C. - VP | T42: D | U42: 6 | V42: 2 | W42: 2026 | X42: 0 | Y42: 0 | Z42: 0.00000000000 | AA42: 0.00 | AB42: 0 | AC42: 0.000000 | AD42: -5896.428 | AE42: 0.00 | AF42: 2075 | AG42: =_xlfn.XLOOKUP(AF42,Planilha2!B:B,Planilha2!A:A,0,0) -> RZF-9F40 | AH42: FIN | AI42: 3 | AJ42: OPERACIONAL | AK42: 14 | AL42: 3 | AM42: L | AN42: ISABELA.SILVA | AO42: NULL | AP42: NULL | AQ42: 2021-09-14 00:00:00.000
A43: FIN | B43: REALIZADO | C43: 000011985ME0022 | D43: 872 | E43: 1 | F43: FIN | G43: 2026-05-28 08:52:00.000 | H43: NULL | I43: 109 | J43: 21 | K43: TRANSFERÊNCIA URBANA - EMPURRADA | L43: 112 | M43: OPERALOG AMAZÔNIA - CAMAÇARI | N43: 35 | O43: OPERACIONAL | P43: 149 | Q43: FINANCIAMENTOS DE VEÍCULOS PESADOS - VP | R43: 61 | S43: C.D.C. - VP | T43: D | U43: 5 | V43: 2 | W43: 2026 | X43: 0 | Y43: 0 | Z43: 0.00000000000 | AA43: 0.00 | AB43: 0 | AC43: 0.000000 | AD43: -15941.1 | AE43: 0.00 | AF43: 590OP | AG43: =_xlfn.XLOOKUP(AF43,Planilha2!B:B,Planilha2!A:A,0,0) -> QYW-2D78 | AH43: FIN | AI43: 3 | AJ43: OPERACIONAL | AK43: 14 | AL43: 3 | AM43: L | AN43: ISABELA.SILVA | AO43: NULL | AP43: NULL | AQ43: 2024-08-01 00:00:00.000
A44: FIN | B44: REALIZADO | C44: 000002090ME0048 | D44: 119473 | E44: 1 | F44: FIN | G44: 2026-07-30 09:39:00.000 | H44: NULL | I44: 19 | J44: 21 | K44: TRANSFERÊNCIA URBANA - EMPURRADA | L44: 112 | M44: OPERALOG AMAZÔNIA - CAMAÇARI | N44: 35 | O44: OPERACIONAL | P44: 149 | Q44: FINANCIAMENTOS DE VEÍCULOS PESADOS - VP | R44: 61 | S44: C.D.C. - VP | T44: D | U44: 8 | V44: 3 | W44: 2026 | X44: 0 | Y44: 0 | Z44: 0.00000000000 | AA44: 0.00 | AB44: 0 | AC44: 0.000000 | AD44: -25085.47 | AE44: 0.00 | AF44: 2510 | AG44: =_xlfn.XLOOKUP(AF44,Planilha2!B:B,Planilha2!A:A,0,0) -> RPH-9D43 | AH44: FIN | AI44: 3 | AJ44: OPERACIONAL | AK44: 14 | AL44: 3 | AM44: L | AN44: ISABELA.SILVA | AO44: NULL | AP44: NULL | AQ44: 2022-07-28 00:00:00.000
A45: FIN | B45: REALIZADO | C45: 000001822ME0057 | D45: 119473 | E45: 1 | F45: FIN | G45: 2026-05-26 17:15:00.000 | H45: NULL | I45: 27 | J45: 21 | K45: TRANSFERÊNCIA URBANA - EMPURRADA | L45: 112 | M45: OPERALOG AMAZÔNIA - CAMAÇARI | N45: 35 | O45: OPERACIONAL | P45: 149 | Q45: FINANCIAMENTOS DE VEÍCULOS PESADOS - VP | R45: 61 | S45: C.D.C. - VP | T45: D | U45: 6 | V45: 2 | W45: 2026 | X45: 0 | Y45: 0 | Z45: 0.00000000000 | AA45: 0.00 | AB45: 0 | AC45: 0.000000 | AD45: -5896.428 | AE45: 0.00 | AF45: 2077 | AG45: =_xlfn.XLOOKUP(AF45,Planilha2!B:B,Planilha2!A:A,0,0) -> RZF-9F80 | AH45: FIN | AI45: 3 | AJ45: OPERACIONAL | AK45: 14 | AL45: 3 | AM45: L | AN45: ISABELA.SILVA | AO45: NULL | AP45: NULL | AQ45: 2021-09-14 00:00:00.000
A46: FIN | B46: REALIZADO | C46: 000001849ME0055 | D46: 119473 | E46: 1 | F46: FIN | G46: 2026-04-29 12:55:00.000 | H46: NULL | I46: 27 | J46: 21 | K46: TRANSFERÊNCIA URBANA - EMPURRADA | L46: 112 | M46: OPERALOG AMAZÔNIA - CAMAÇARI | N46: 35 | O46: OPERACIONAL | P46: 149 | Q46: FINANCIAMENTOS DE VEÍCULOS PESADOS - VP | R46: 61 | S46: C.D.C. - VP | T46: D | U46: 5 | V46: 2 | W46: 2026 | X46: 0 | Y46: 0 | Z46: 0.00000000000 | AA46: 0.00 | AB46: 0 | AC46: 0.000000 | AD46: -6447.322 | AE46: 0.00 | AF46: 2037 | AG46: =_xlfn.XLOOKUP(AF46,Planilha2!B:B,Planilha2!A:A,0,0) -> RZF-8B28 | AH46: FIN | AI46: 3 | AJ46: OPERACIONAL | AK46: 14 | AL46: 3 | AM46: L | AN46: ISABELA.SILVA | AO46: NULL | AP46: NULL | AQ46: 2021-11-01 00:00:00.000
A47: FIN | B47: REALIZADO | C47: 000001736ME0060 | D47: 119473 | E47: 1 | F47: FIN | G47: 2026-05-28 13:07:00.000 | H47: NULL | I47: 27 | J47: 21 | K47: TRANSFERÊNCIA URBANA - EMPURRADA | L47: 112 | M47: OPERALOG AMAZÔNIA - CAMAÇARI | N47: 35 | O47: OPERACIONAL | P47: 149 | Q47: FINANCIAMENTOS DE VEÍCULOS PESADOS - VP | R47: 61 | S47: C.D.C. - VP | T47: D | U47: 6 | V47: 2 | W47: 2026 | X47: 0 | Y47: 0 | Z47: 0.00000000000 | AA47: 0.00 | AB47: 0 | AC47: 0.000000 | AD47: -10027.84 | AE47: 0.00 | AF47: 2254 | AG47: =_xlfn.XLOOKUP(AF47,Planilha2!B:B,Planilha2!A:A,0,0) -> QYX-2C72 | AH47: FIN | AI47: 3 | AJ47: OPERACIONAL | AK47: 14 | AL47: 3 | AM47: L | AN47: ISABELA.SILVA | AO47: NULL | AP47: NULL | AQ47: 2021-06-28 00:00:00.000
A48: FIN | B48: REALIZADO | C48: 000002089ME0045 | D48: 119473 | E48: 1 | F48: FIN | G48: 2026-04-28 15:06:00.000 | H48: NULL | I48: 19 | J48: 21 | K48: TRANSFERÊNCIA URBANA - EMPURRADA | L48: 112 | M48: OPERALOG AMAZÔNIA - CAMAÇARI | N48: 35 | O48: OPERACIONAL | P48: 149 | Q48: FINANCIAMENTOS DE VEÍCULOS PESADOS - VP | R48: 61 | S48: C.D.C. - VP | T48: D | U48: 5 | V48: 2 | W48: 2026 | X48: 0 | Y48: 0 | Z48: 0.00000000000 | AA48: 0.00 | AB48: 0 | AC48: 0.000000 | AD48: -25085.47 | AE48: 0.00 | AF48: 2528 | AG48: =_xlfn.XLOOKUP(AF48,Planilha2!B:B,Planilha2!A:A,0,0) -> RPG-7A20 | AH48: FIN | AI48: 3 | AJ48: OPERACIONAL | AK48: 14 | AL48: 3 | AM48: L | AN48: ISABELA.SILVA | AO48: NULL | AP48: NULL | AQ48: 2022-07-28 00:00:00.000
A49: FIN | B49: REALIZADO | C49: 000002089ME0047 | D49: 119473 | E49: 1 | F49: FIN | G49: 2026-06-19 16:42:00.000 | H49: NULL | I49: 19 | J49: 21 | K49: TRANSFERÊNCIA URBANA - EMPURRADA | L49: 112 | M49: OPERALOG AMAZÔNIA - CAMAÇARI | N49: 35 | O49: OPERACIONAL | P49: 149 | Q49: FINANCIAMENTOS DE VEÍCULOS PESADOS - VP | R49: 61 | S49: C.D.C. - VP | T49: D | U49: 7 | V49: 3 | W49: 2026 | X49: 0 | Y49: 0 | Z49: 0.00000000000 | AA49: 0.00 | AB49: 0 | AC49: 0.000000 | AD49: -25085.47 | AE49: 0.00 | AF49: 2524 | AG49: =_xlfn.XLOOKUP(AF49,Planilha2!B:B,Planilha2!A:A,0,0) -> RPG-5D53 | AH49: FIN | AI49: 3 | AJ49: OPERACIONAL | AK49: 14 | AL49: 3 | AM49: L | AN49: ISABELA.SILVA | AO49: NULL | AP49: NULL | AQ49: 2022-07-28 00:00:00.000
A50: FIN | B50: REALIZADO | C50: 000002089ME0045 | D50: 119473 | E50: 1 | F50: FIN | G50: 2026-04-28 15:06:00.000 | H50: NULL | I50: 19 | J50: 21 | K50: TRANSFERÊNCIA URBANA - EMPURRADA | L50: 112 | M50: OPERALOG AMAZÔNIA - CAMAÇARI | N50: 35 | O50: OPERACIONAL | P50: 149 | Q50: FINANCIAMENTOS DE VEÍCULOS PESADOS - VP | R50: 61 | S50: C.D.C. - VP | T50: D | U50: 5 | V50: 2 | W50: 2026 | X50: 0 | Y50: 0 | Z50: 0.00000000000 | AA50: 0.00 | AB50: 0 | AC50: 0.000000 | AD50: -25085.47 | AE50: 0.00 | AF50: 2532 | AG50: =_xlfn.XLOOKUP(AF50,Planilha2!B:B,Planilha2!A:A,0,0) -> RPG-1J60 | AH50: FIN | AI50: 3 | AJ50: OPERACIONAL | AK50: 14 | AL50: 3 | AM50: L | AN50: ISABELA.SILVA | AO50: NULL | AP50: NULL | AQ50: 2022-07-28 00:00:00.000
A51: FIN | B51: REALIZADO | C51: 000001822ME0059 | D51: 119473 | E51: 1 | F51: FIN | G51: 2026-07-30 09:03:00.000 | H51: NULL | I51: 27 | J51: 21 | K51: TRANSFERÊNCIA URBANA - EMPURRADA | L51: 112 | M51: OPERALOG AMAZÔNIA - CAMAÇARI | N51: 35 | O51: OPERACIONAL | P51: 149 | Q51: FINANCIAMENTOS DE VEÍCULOS PESADOS - VP | R51: 61 | S51: C.D.C. - VP | T51: D | U51: 8 | V51: 3 | W51: 2026 | X51: 0 | Y51: 0 | Z51: 0.00000000000 | AA51: 0.00 | AB51: 0 | AC51: 0.000000 | AD51: -5896.428 | AE51: 0.00 | AF51: 2077 | AG51: =_xlfn.XLOOKUP(AF51,Planilha2!B:B,Planilha2!A:A,0,0) -> RZF-9F80 | AH51: FIN | AI51: 3 | AJ51: OPERACIONAL | AK51: 14 | AL51: 3 | AM51: L | AN51: ISABELA.SILVA | AO51: NULL | AP51: NULL | AQ51: 2021-09-14 00:00:00.000
A52: FIN | B52: REALIZADO | C52: 000001822ME0059 | D52: 119473 | E52: 1 | F52: FIN | G52: 2026-07-30 09:03:00.000 | H52: NULL | I52: 27 | J52: 21 | K52: TRANSFERÊNCIA URBANA - EMPURRADA | L52: 112 | M52: OPERALOG AMAZÔNIA - CAMAÇARI | N52: 35 | O52: OPERACIONAL | P52: 149 | Q52: FINANCIAMENTOS DE VEÍCULOS PESADOS - VP | R52: 61 | S52: C.D.C. - VP | T52: D | U52: 8 | V52: 3 | W52: 2026 | X52: 0 | Y52: 0 | Z52: 0.00000000000 | AA52: 0.00 | AB52: 0 | AC52: 0.000000 | AD52: -5896.428 | AE52: 0.00 | AF52: 2075 | AG52: =_xlfn.XLOOKUP(AF52,Planilha2!B:B,Planilha2!A:A,0,0) -> RZF-9F40 | AH52: FIN | AI52: 3 | AJ52: OPERACIONAL | AK52: 14 | AL52: 3 | AM52: L | AN52: ISABELA.SILVA | AO52: NULL | AP52: NULL | AQ52: 2021-09-14 00:00:00.000
A53: FIN | B53: REALIZADO | C53: 000001847ME0054 | D53: 119473 | E53: 1 | F53: FIN | G53: 2026-03-25 17:36:00.000 | H53: NULL | I53: 27 | J53: 21 | K53: TRANSFERÊNCIA URBANA - EMPURRADA | L53: 112 | M53: OPERALOG AMAZÔNIA - CAMAÇARI | N53: 35 | O53: OPERACIONAL | P53: 149 | Q53: FINANCIAMENTOS DE VEÍCULOS PESADOS - VP | R53: 61 | S53: C.D.C. - VP | T53: D | U53: 4 | V53: 2 | W53: 2026 | X53: 0 | Y53: 0 | Z53: 0.00000000000 | AA53: 0.00 | AB53: 0 | AC53: 0.000000 | AD53: -6447.322 | AE53: 0.00 | AF53: 2021 | AG53: =_xlfn.XLOOKUP(AF53,Planilha2!B:B,Planilha2!A:A,0,0) -> RZF-8E78 | AH53: FIN | AI53: 3 | AJ53: OPERACIONAL | AK53: 14 | AL53: 3 | AM53: L | AN53: ISABELA.SILVA | AO53: NULL | AP53: NULL | AQ53: 2021-11-08 00:00:00.000
A54: FIN | B54: REALIZADO | C54: 000001848ME0054 | D54: 119473 | E54: 1 | F54: FIN | G54: 2026-03-26 09:03:00.000 | H54: NULL | I54: 27 | J54: 21 | K54: TRANSFERÊNCIA URBANA - EMPURRADA | L54: 112 | M54: OPERALOG AMAZÔNIA - CAMAÇARI | N54: 35 | O54: OPERACIONAL | P54: 149 | Q54: FINANCIAMENTOS DE VEÍCULOS PESADOS - VP | R54: 61 | S54: C.D.C. - VP | T54: D | U54: 4 | V54: 2 | W54: 2026 | X54: 0 | Y54: 0 | Z54: 0.00000000000 | AA54: 0.00 | AB54: 0 | AC54: 0.000000 | AD54: -6447.322 | AE54: 0.00 | AF54: 2033 | AG54: =_xlfn.XLOOKUP(AF54,Planilha2!B:B,Planilha2!A:A,0,0) -> RZG-4A80 | AH54: FIN | AI54: 3 | AJ54: OPERACIONAL | AK54: 14 | AL54: 3 | AM54: L | AN54: ISABELA.SILVA | AO54: NULL | AP54: NULL | AQ54: 2021-11-04 00:00:00.000
A55: FIN | B55: REALIZADO | C55: 000001852ME0057 | D55: 119473 | E55: 1 | F55: FIN | G55: 2026-06-26 10:42:00.000 | H55: NULL | I55: 27 | J55: 21 | K55: TRANSFERÊNCIA URBANA - EMPURRADA | L55: 112 | M55: OPERALOG AMAZÔNIA - CAMAÇARI | N55: 35 | O55: OPERACIONAL | P55: 149 | Q55: FINANCIAMENTOS DE VEÍCULOS PESADOS - VP | R55: 61 | S55: C.D.C. - VP | T55: D | U55: 7 | V55: 3 | W55: 2026 | X55: 0 | Y55: 0 | Z55: 0.00000000000 | AA55: 0.00 | AB55: 0 | AC55: 0.000000 | AD55: -6447.322 | AE55: 0.00 | AF55: 2055 | AG55: =_xlfn.XLOOKUP(AF55,Planilha2!B:B,Planilha2!A:A,0,0) -> RZF-8D48 | AH55: FIN | AI55: 3 | AJ55: OPERACIONAL | AK55: 14 | AL55: 3 | AM55: L | AN55: ISABELA.SILVA | AO55: NULL | AP55: NULL | AQ55: 2021-11-04 00:00:00.000
... A58: FIN | B58: REALIZADO | C58: 000011213ME0038 | D58: 21009 | E58: 1 | F58: FIN | G58: 2026-03-17 16:47:00.000 | H58: NULL | I58: 12 | J58: 21 | K58: TRANSFERÊNCIA URBANA - EMPURRADA | L58: 112 | M58: OPERALOG AMAZÔNIA - CAMAÇARI | N58: 35 | O58: OPERACIONAL | P58: 149 | Q58: FINANCIAMENTOS DE VEÍCULOS PESADOS - VP | R58: 61 | S58: C.D.C. - VP | T58: D | U58: 3 | V58: 1 | W58: 2026 | X58: 0 | Y58: 0 | Z58: 0.00000000000 | AA58: 0.00 | AB58: 0 | AC58: 0.000000 | AD58: -17725.04 | AE58: 0.00 | AF58: 2476 | AG58: =_xlfn.XLOOKUP(AF58,Planilha2!B:B,Planilha2!A:A,0,0) -> RPG-1B56 | AH58: FIN | AI58: 3 | AJ58: OPERACIONAL | AK58: 14 | AL58: 3 | AM58: L | AN58: ISABELA.SILVA | AO58: NULL | AP58: NULL | AQ58: 2022-07-14 00:00:00.000
A59: FIN | B59: REALIZADO | C59: 000011522ME0036 | D59: 69551 | E59: 1 | F59: FIN | G59: 2023-08-18 13:15:00.000 | H59: NULL | I59: 109 | J59: 21 | K59: TRANSFERÊNCIA URBANA - EMPURRADA | L59: 112 | M59: OPERALOG AMAZÔNIA - CAMAÇARI | N59: 35 | O59: OPERACIONAL | P59: 149 | Q59: FINANCIAMENTOS DE VEÍCULOS PESADOS - VP | R59: 61 | S59: C.D.C. - VP | T59: D | U59: 6 | V59: 2 | W59: 2026 | X59: 0 | Y59: 0 | Z59: 0.00000000000 | AA59: 0.00 | AB59: 0 | AC59: 0.000000 | AD59: -5540.83 | AE59: 0.00 | AF59: 618OP | AG59: =_xlfn.XLOOKUP(AF59,Planilha2!B:B,Planilha2!A:A,0,0) -> RPO-0J60 | AH59: FIN | AI59: 3 | AJ59: OPERACIONAL | AK59: 14 | AL59: 3 | AM59: L | AN59: ANA.PESSOA | AO59: NULL | AP59: NULL | AQ59: 2022-12-20 00:00:00.000
A60: FIN | B60: REALIZADO | C60: 000002088ME0043 | D60: 119473 | E60: 1 | F60: FIN | G60: 2026-01-23 12:45:00.000 | H60: NULL | I60: 19 | J60: 21 | K60: TRANSFERÊNCIA URBANA - EMPURRADA | L60: 112 | M60: OPERALOG AMAZÔNIA - CAMAÇARI | N60: 35 | O60: OPERACIONAL | P60: 149 | Q60: FINANCIAMENTOS DE VEÍCULOS PESADOS - VP | R60: 61 | S60: C.D.C. - VP | T60: D | U60: 3 | V60: 1 | W60: 2026 | X60: 0 | Y60: 0 | Z60: 0.00000000000 | AA60: 0.00 | AB60: 0 | AC60: 0.000000 | AD60: -25085.47 | AE60: 0.00 | AF60: 2486 | AG60: =_xlfn.XLOOKUP(AF60,Planilha2!B:B,Planilha2!A:A,0,0) -> RPG-0C44 | AH60: FIN | AI60: 3 | AJ60: OPERACIONAL | AK60: 14 | AL60: 3 | AM60: L | AN60: ISABELA.SILVA | AO60: NULL | AP60: NULL | AQ60: 2022-07-28 00:00:00.000
A61: FIN | B61: REALIZADO | C61: 000011431ME0035 | D61: 42128 | E61: 1 | F61: FIN | G61: 2026-05-27 11:15:00.000 | H61: NULL | I61: 19 | J61: 21 | K61: TRANSFERÊNCIA URBANA - EMPURRADA | L61: 112 | M61: OPERALOG AMAZÔNIA - CAMAÇARI | N61: 35 | O61: OPERACIONAL | P61: 149 | Q61: FINANCIAMENTOS DE VEÍCULOS PESADOS - VP | R61: 61 | S61: C.D.C. - VP | T61: D | U61: 6 | V61: 2 | W61: 2026 | X61: 0 | Y61: 0 | Z61: 0.00000000000 | AA61: 0.00 | AB61: 0 | AC61: 0.000000 | AD61: -5450.755 | AE61: 0.00 | AF61: 2534 | AG61: =_xlfn.XLOOKUP(AF61,Planilha2!B:B,Planilha2!A:A,0,0) -> RPH-9E62 | AH61: FIN | AI61: 3 | AJ61: OPERACIONAL | AK61: 14 | AL61: 3 | AM61: L | AN61: ISABELA.SILVA | AO61: NULL | AP61: NULL | AQ61: 2022-08-09 00:00:00.000
A62: FIN | B62: REALIZADO | C62: 000011210ME0043 | D62: 21009 | E62: 1 | F62: FIN | G62: 2026-07-31 09:51:00.000 | H62: NULL | I62: 12 | J62: 21 | K62: TRANSFERÊNCIA URBANA - EMPURRADA | L62: 112 | M62: OPERALOG AMAZÔNIA - CAMAÇARI | N62: 35 | O62: OPERACIONAL | P62: 149 | Q62: FINANCIAMENTOS DE VEÍCULOS PESADOS - VP | R62: 61 | S62: C.D.C. - VP | T62: D | U62: 8 | V62: 3 | W62: 2026 | X62: 0 | Y62: 0 | Z62: 0.00000000000 | AA62: 0.00 | AB62: 0 | AC62: 0.000000 | AD62: -17725.04 | AE62: 0.00 | AF62: 2482 | AG62: =_xlfn.XLOOKUP(AF62,Planilha2!B:B,Planilha2!A:A,0,0) -> RPG-1D47 | AH62: FIN | AI62: 3 | AJ62: OPERACIONAL | AK62: 14 | AL62: 3 | AM62: L | AN62: ISABELA.SILVA | AO62: NULL | AP62: NULL | AQ62: 2022-07-14 00:00:00.000
A63: FIN | B63: REALIZADO | C63: 000011207ME0041 | D63: 21009 | E63: 1 | F63: FIN | G63: 2026-05-26 15:43:00.000 | H63: NULL | I63: 12 | J63: 21 | K63: TRANSFERÊNCIA URBANA - EMPURRADA | L63: 112 | M63: OPERALOG AMAZÔNIA - CAMAÇARI | N63: 35 | O63: OPERACIONAL | P63: 149 | Q63: FINANCIAMENTOS DE VEÍCULOS PESADOS - VP | R63: 61 | S63: C.D.C. - VP | T63: D | U63: 6 | V63: 2 | W63: 2026 | X63: 0 | Y63: 0 | Z63: 0.00000000000 | AA63: 0.00 | AB63: 0 | AC63: 0.000000 | AD63: -17725.04 | AE63: 0.00 | AF63: 2472 | AG63: =_xlfn.XLOOKUP(AF63,Planilha2!B:B,Planilha2!A:A,0,0) -> RPG-4D60 | AH63: FIN | AI63: 3 | AJ63: OPERACIONAL | AK63: 14 | AL63: 3 | AM63: L | AN63: ISABELA.SILVA | AO63: NULL | AP63: NULL | AQ63: 2022-07-14 00:00:00.000
A64: FIN | B64: REALIZADO | C64: 000011209ME0038 | D64: 21009 | E64: 1 | F64: FIN | G64: 2026-03-17 16:46:00.000 | H64: NULL | I64: 12 | J64: 21 | K64: TRANSFERÊNCIA URBANA - EMPURRADA | L64: 112 | M64: OPERALOG AMAZÔNIA - CAMAÇARI | N64: 35 | O64: OPERACIONAL | P64: 149 | Q64: FINANCIAMENTOS DE VEÍCULOS PESADOS - VP | R64: 61 | S64: C.D.C. - VP | T64: D | U64: 3 | V64: 1 | W64: 2026 | X64: 0 | Y64: 0 | Z64: 0.00000000000 | AA64: 0.00 | AB64: 0 | AC64: 0.000000 | AD64: -17725.04 | AE64: 0.00 | AF64: 2468 | AG64: =_xlfn.XLOOKUP(AF64,Planilha2!B:B,Planilha2!A:A,0,0) -> RPG-9B10 | AH64: FIN | AI64: 3 | AJ64: OPERACIONAL | AK64: 14 | AL64: 3 | AM64: L | AN64: ISABELA.SILVA | AO64: NULL | AP64: NULL | AQ64: 2022-07-14 00:00:00.000
A65: FIN | B65: REALIZADO | C65: 000002088ME0042 | D65: 119473 | E65: 1 | F65: FIN | G65: 2026-01-07 13:02:00.000 | H65: NULL | I65: 19 | J65: 21 | K65: TRANSFERÊNCIA URBANA - EMPURRADA | L65: 112 | M65: OPERALOG AMAZÔNIA - CAMAÇARI | N65: 35 | O65: OPERACIONAL | P65: 149 | Q65: FINANCIAMENTOS DE VEÍCULOS PESADOS - VP | R65: 61 | S65: C.D.C. - VP | T65: D | U65: 2 | V65: 1 | W65: 2026 | X65: 0 | Y65: 0 | Z65: 0.00000000000 | AA65: 0.00 | AB65: 0 | AC65: 0.000000 | AD65: -25085.47 | AE65: 0.00 | AF65: 2484 | AG65: =_xlfn.XLOOKUP(AF65,Planilha2!B:B,Planilha2!A:A,0,0) -> RPG-2G75 | AH65: FIN | AI65: 3 | AJ65: OPERACIONAL | AK65: 14 | AL65: 3 | AM65: L | AN65: ISABELA.SILVA | AO65: NULL | AP65: NULL | AQ65: 2022-07-28 00:00:00.000
A66: FIN | B66: REALIZADO | C66: 000011518ME0034 | D66: 69551 | E66: 1 | F66: FIN | G66: 2023-08-16 17:23:00.000 | H66: NULL | I66: 109 | J66: 21 | K66: TRANSFERÊNCIA URBANA - EMPURRADA | L66: 112 | M66: OPERALOG AMAZÔNIA - CAMAÇARI | N66: 35 | O66: OPERACIONAL | P66: 149 | Q66: FINANCIAMENTOS DE VEÍCULOS PESADOS - VP | R66: 61 | S66: C.D.C. - VP | T66: D | U66: 6 | V66: 2 | W66: 2026 | X66: 0 | Y66: 0 | Z66: 0.00000000000 | AA66: 0.00 | AB66: 0 | AC66: 0.000000 | AD66: -22859.57 | AE66: 0.00 | AF66: 619OP | AG66: =_xlfn.XLOOKUP(AF66,Planilha2!B:B,Planilha2!A:A,0,0) -> RZW-6G32 | AH66: FIN | AI66: 3 | AJ66: OPERACIONAL | AK66: 14 | AL66: 3 | AM66: L | AN66: ANA.PESSOA | AO66: NULL | AP66: NULL | AQ66: 2023-02-13 00:00:00.000
A67: FIN | B67: REALIZADO | C67: 000011518ME0036 | D67: 69551 | E67: 1 | F67: FIN | G67: 2023-08-16 17:23:00.000 | H67: NULL | I67: 109 | J67: 21 | K67: TRANSFERÊNCIA URBANA - EMPURRADA | L67: 112 | M67: OPERALOG AMAZÔNIA - CAMAÇARI | N67: 35 | O67: OPERACIONAL | P67: 149 | Q67: FINANCIAMENTOS DE VEÍCULOS PESADOS - VP | R67: 61 | S67: C.D.C. - VP | T67: D | U67: 8 | V67: 3 | W67: 2026 | X67: 0 | Y67: 0 | Z67: 0.00000000000 | AA67: 0.00 | AB67: 0 | AC67: 0.000000 | AD67: -22859.57 | AE67: 0.00 | AF67: 619OP | AG67: =_xlfn.XLOOKUP(AF67,Planilha2!B:B,Planilha2!A:A,0,0) -> RZW-6G32 | AH67: FIN | AI67: 3 | AJ67: OPERACIONAL | AK67: 14 | AL67: 3 | AM67: L | AN67: ANA.PESSOA | AO67: NULL | AP67: NULL | AQ67: 2023-02-13 00:00:00.000
A68: FIN | B68: REALIZADO | C68: 000002088ME0043 | D68: 119473 | E68: 1 | F68: FIN | G68: 2026-01-23 12:45:00.000 | H68: NULL | I68: 19 | J68: 21 | K68: TRANSFERÊNCIA URBANA - EMPURRADA | L68: 112 | M68: OPERALOG AMAZÔNIA - CAMAÇARI | N68: 35 | O68: OPERACIONAL | P68: 149 | Q68: FINANCIAMENTOS DE VEÍCULOS PESADOS - VP | R68: 61 | S68: C.D.C. - VP | T68: D | U68: 3 | V68: 1 | W68: 2026 | X68: 0 | Y68: 0 | Z68: 0.00000000000 | AA68: 0.00 | AB68: 0 | AC68: 0.000000 | AD68: -25085.47 | AE68: 0.00 | AF68: 2490 | AG68: =_xlfn.XLOOKUP(AF68,Planilha2!B:B,Planilha2!A:A,0,0) -> RPG-3A89 | AH68: FIN | AI68: 3 | AJ68: OPERACIONAL | AK68: 14 | AL68: 3 | AM68: L | AN68: ISABELA.SILVA | AO68: NULL | AP68: NULL | AQ68: 2022-07-28 00:00:00.000
A69: FIN | B69: REALIZADO | C69: 000011431ME0031 | D69: 42128 | E69: 1 | F69: FIN | G69: 2026-01-29 11:59:00.000 | H69: NULL | I69: 19 | J69: 21 | K69: TRANSFERÊNCIA URBANA - EMPURRADA | L69: 112 | M69: OPERALOG AMAZÔNIA - CAMAÇARI | N69: 35 | O69: OPERACIONAL | P69: 149 | Q69: FINANCIAMENTOS DE VEÍCULOS PESADOS - VP | R69: 61 | S69: C.D.C. - VP | T69: D | U69: 2 | V69: 1 | W69: 2026 | X69: 0 | Y69: 0 | Z69: 0.00000000000 | AA69: 0.00 | AB69: 0 | AC69: 0.000000 | AD69: -5450.755 | AE69: 0.00 | AF69: 2534 | AG69: =_xlfn.XLOOKUP(AF69,Planilha2!B:B,Planilha2!A:A,0,0) -> RPH-9E62 | AH69: FIN | AI69: 3 | AJ69: OPERACIONAL | AK69: 14 | AL69: 3 | AM69: L | AN69: ISABELA.SILVA | AO69: NULL | AP69: NULL | AQ69: 2022-08-09 00:00:00.000
A70: FIN | B70: REALIZADO | C70: 000011209ME0043 | D70: 21009 | E70: 1 | F70: FIN | G70: 2026-07-31 09:59:00.000 | H70: NULL | I70: 12 | J70: 21 | K70: TRANSFERÊNCIA URBANA - EMPURRADA | L70: 112 | M70: OPERALOG AMAZÔNIA - CAMAÇARI | N70: 35 | O70: OPERACIONAL | P70: 149 | Q70: FINANCIAMENTOS DE VEÍCULOS PESADOS - VP | R70: 61 | S70: C.D.C. - VP | T70: D | U70: 8 | V70: 3 | W70: 2026 | X70: 0 | Y70: 0 | Z70: 0.00000000000 | AA70: 0.00 | AB70: 0 | AC70: 0.000000 | AD70: -17725.04 | AE70: 0.00 | AF70: 2468 | AG70: =_xlfn.XLOOKUP(AF70,Planilha2!B:B,Planilha2!A:A,0,0) -> RPG-9B10 | AH70: FIN | AI70: 3 | AJ70: OPERACIONAL | AK70: 14 | AL70: 3 | AM70: L | AN70: ISABELA.SILVA | AO70: NULL | AP70: NULL | AQ70: 2022-07-14 00:00:00.000
...

Sheet Planilha2
A1: numvei | B1: codvei
A2: KJL-0946 | B2: KJL0946
A3: PPA-0646 | B3: 028
A4: NBB-0102 | B4: 02E
A5: NNH-0450 | B5: 0450
A6: OYF-6929 | B6: 077
A7: EEZ-7458 | B7: 082019
A8: MZG-0834 | B8: 0834
A9: NMI-0867 | B9: 0867
A10: HUH-1777 | B10: 1
A11: KJX-0970 | B11: 1000E
A12: OTX-7562 | B12: 1001
A13: KJW-1490 | B13: 1002E
A14: OTV-9521 | B14: 1003
A15: KJT-9960 | B15: 1004E
A16: OTX-7552 | B16: 1005
A17: KJR-9170 | B17: 1006E
A18: OTX-7H02 | B18: 1007
A19: KJQ-2440 | B19: 1008E
A20: OTX-7782 | B20: 1009
A21: PFK-0932 | B21: 100E
A22: PEG-0000 | B22: 101
A23: NDS-6267 | B23: 1010E
A24: CQH-5741 | B24: 1011
A25: OTX-7G32 | B25: 1011E
A26: NDS-6297 | B26: 1012E
A27: CQH-5983 | B27: 1013
A28: OTX-7592 | B28: 1013E
A29: NDS-6287 | B29: 1014E
A30: CQH-2718 | B30: 1015
A31: OTX-7612 | B31: 1015E
A32: NCD-4891 | B32: 1016E
A33: CQH-6022 | B33: 1017
A34: OTX-7602 | B34: 1017E
A35: NDS-6277 | B35: 1018E
A36: OTX-7582 | B36: 1019E
A37: RTI-5B06 | B37: 101AL
A38: PEG-1222 | B38: 101E
A39: PEM-0000 | B39: 102
A40: PDM-7D90 | B40: 1020
...
