Workbook

Sheet KM RODADO
A1: CORREÇÃO TMA LUCRO DESTINO
A2: Trecho | B2: Pallets: 28 | C2: Pallets: 30 | D2: Correção FT | E2: Trecho FT | F2: ID FT
A3: BR04xBR04x29021610.0 | B3: =_xlfn.XLOOKUP(A3&$B$2,Trecho!B:B,Trecho!BR:BR) -> 64 | C3: =_xlfn.XLOOKUP(A3&$C$2,Trecho!B:B,Trecho!BR:BR) -> 79.24 | D3: =IF(C3>B3,"30 MAIOR",IF(B3=C3,"OK","Corrigir")) -> 30 MAIOR | E3: =_xlfn.XLOOKUP(A3&$C$2,Trecho!B:B,Trecho!AD:AD) -> CERVEJARIA CAMAÇARI_10261249-SENDAS DISTRIBUIDORA SA(S4)_30_false | F3: =_xlfn.XLOOKUP(A3&$C$2,Trecho!B:B,Trecho!DH:DH) -> 70528b4a-84b1-478c-b1e4-6b36a04408e9
A4: BR04xBR04x29021490.0 | B4: =_xlfn.XLOOKUP(A4&$B$2,Trecho!B:B,Trecho!BR:BR) -> 1012 | C4: =_xlfn.XLOOKUP(A4&$C$2,Trecho!B:B,Trecho!BR:BR) -> 1012.78 | D4: =IF(C4>B4,"30 MAIOR",IF(B4=C4,"OK","Corrigir")) -> 30 MAIOR | E4: =_xlfn.XLOOKUP(A4&$C$2,Trecho!B:B,Trecho!AD:AD) -> CERVEJARIA CAMAÇARI_10261166-SENDAS DISTRIBUIDORA SA(S4)_30_false | F4: =_xlfn.XLOOKUP(A4&$C$2,Trecho!B:B,Trecho!DH:DH) -> f9696d56-1cc1-4625-ae94-5a2a140653a5
A5: BR04xBR04x29021355.0 | B5: =_xlfn.XLOOKUP(A5&$B$2,Trecho!B:B,Trecho!BR:BR) -> 1173.41 | C5: =_xlfn.XLOOKUP(A5&$C$2,Trecho!B:B,Trecho!BR:BR) -> 1149.92 | D5: =IF(C5>B5,"30 MAIOR",IF(B5=C5,"OK","Corrigir")) -> Corrigir | E5: =_xlfn.XLOOKUP(A5&$C$2,Trecho!B:B,Trecho!AD:AD) -> CERVEJARIA CAMAÇARI_10261066- SENDAS DISTRIBUIDORA SA (S4)_30_false | F5: =_xlfn.XLOOKUP(A5&$C$2,Trecho!B:B,Trecho!DH:DH) -> 3fdbe4f1-0311-487a-b1f3-105b01c5b1ef
A6: BR04xBR04x29021307.0 | B6: =_xlfn.XLOOKUP(A6&$B$2,Trecho!B:B,Trecho!BR:BR) -> 1078 | C6: =_xlfn.XLOOKUP(A6&$C$2,Trecho!B:B,Trecho!BR:BR) -> 989.24 | D6: =IF(C6>B6,"30 MAIOR",IF(B6=C6,"OK","Corrigir")) -> Corrigir | E6: =_xlfn.XLOOKUP(A6&$C$2,Trecho!B:B,Trecho!AD:AD) -> CERVEJARIA CAMAÇARI_10261027-SENDAS DISTRIBUIDORA SA(S4)_30_false | F6: =_xlfn.XLOOKUP(A6&$C$2,Trecho!B:B,Trecho!DH:DH) -> 2d191341-41c1-4e6a-9702-a37db2d97278
A7: BR04xBR04x29021312.0 | B7: =_xlfn.XLOOKUP(A7&$B$2,Trecho!B:B,Trecho!BR:BR) -> 1562.25 | C7: =_xlfn.XLOOKUP(A7&$C$2,Trecho!B:B,Trecho!BR:BR) -> 1560 | D7: =IF(C7>B7,"30 MAIOR",IF(B7=C7,"OK","Corrigir")) -> Corrigir | E7: =_xlfn.XLOOKUP(A7&$C$2,Trecho!B:B,Trecho!AD:AD) -> CERVEJARIA CAMAÇARI_10261032- SENDAS DISTRIBUIDORA S/A LJ119 (S4)_30_false | F7: =_xlfn.XLOOKUP(A7&$C$2,Trecho!B:B,Trecho!DH:DH) -> 524e16ac-a1f4-4333-ab10-277e12c83822
A8: BR04xBR04x29022096.0 | B8: =_xlfn.XLOOKUP(A8&$B$2,Trecho!B:B,Trecho!BR:BR) -> 199.17 | C8: =_xlfn.XLOOKUP(A8&$C$2,Trecho!B:B,Trecho!BR:BR) -> 210.7 | D8: =IF(C8>B8,"30 MAIOR",IF(B8=C8,"OK","Corrigir")) -> 30 MAIOR | E8: =_xlfn.XLOOKUP(A8&$C$2,Trecho!B:B,Trecho!AD:AD) -> CERVEJARIA CAMAÇARI_10261587- ATACADAO S A (S4)_30_false | F8: =_xlfn.XLOOKUP(A8&$C$2,Trecho!B:B,Trecho!DH:DH) -> 02b00b6d-201d-44cd-924e-1b7acc63a6a2
A9: BR04xBR04x29021848.0 | B9: =_xlfn.XLOOKUP(A9&$B$2,Trecho!B:B,Trecho!BR:BR) -> 2342.78 | C9: =_xlfn.XLOOKUP(A9&$C$2,Trecho!B:B,Trecho!BR:BR) -> 2341.84 | D9: =IF(C9>B9,"30 MAIOR",IF(B9=C9,"OK","Corrigir")) -> Corrigir | E9: =_xlfn.XLOOKUP(A9&$C$2,Trecho!B:B,Trecho!AD:AD) -> CERVEJARIA CAMAÇARI_10261402-SUPERMERCADO COMETA LTDA(S4)_30_false | F9: =_xlfn.XLOOKUP(A9&$C$2,Trecho!B:B,Trecho!DH:DH) -> ea8a6297-8102-4be2-90b7-c824eaae8cc3
A10: BR04xBR04x29021611.0 | B10: =_xlfn.XLOOKUP(A10&$B$2,Trecho!B:B,Trecho!BR:BR) -> 109 | C10: =_xlfn.XLOOKUP(A10&$C$2,Trecho!B:B,Trecho!BR:BR) -> 107.96 | D10: =IF(C10>B10,"30 MAIOR",IF(B10=C10,"OK","Corrigir")) -> Corrigir | E10: =_xlfn.XLOOKUP(A10&$C$2,Trecho!B:B,Trecho!AD:AD) -> CERVEJARIA CAMAÇARI_10261250- SENDAS DISTRIBUIDORA SA (S4)_30_false | F10: =_xlfn.XLOOKUP(A10&$C$2,Trecho!B:B,Trecho!DH:DH) -> 8ae9cfbe-1ea5-4262-9e94-8903e3b0e235
A11: BR04xBR04x29023180.0 | B11: =_xlfn.XLOOKUP(A11&$B$2,Trecho!B:B,Trecho!BR:BR) -> 1558.89 | C11: =_xlfn.XLOOKUP(A11&$C$2,Trecho!B:B,Trecho!BR:BR) -> 1598.52 | D11: =IF(C11>B11,"30 MAIOR",IF(B11=C11,"OK","Corrigir")) -> 30 MAIOR | E11: =_xlfn.XLOOKUP(A11&$C$2,Trecho!B:B,Trecho!AD:AD) -> CERVEJARIA CAMAÇARI_10262331-ATACADAO S A(S4)_30_false | F11: =_xlfn.XLOOKUP(A11&$C$2,Trecho!B:B,Trecho!DH:DH) -> 67942aa0-52ec-4eef-a049-4601aaab0dc3
A12: BR04xBR04x29022977.0 | B12: =_xlfn.XLOOKUP(A12&$B$2,Trecho!B:B,Trecho!BR:BR) -> 1559.85 | C12: =_xlfn.XLOOKUP(A12&$C$2,Trecho!B:B,Trecho!BR:BR) -> 1548.12 | D12: =IF(C12>B12,"30 MAIOR",IF(B12=C12,"OK","Corrigir")) -> Corrigir | E12: =_xlfn.XLOOKUP(A12&$C$2,Trecho!B:B,Trecho!AD:AD) -> CERVEJARIA CAMAÇARI_10262178- DISTCARNES DISTRIBUIDORA CARNES (S4)_30_false | F12: =_xlfn.XLOOKUP(A12&$C$2,Trecho!B:B,Trecho!DH:DH) -> 48494a73-80ad-4ac0-9dc7-35f06d15df50
A13: BR04xBR04x29022696.0 | B13: =_xlfn.XLOOKUP(A13&$B$2,Trecho!B:B,Trecho!BR:BR) -> 854 | C13: =_xlfn.XLOOKUP(A13&$C$2,Trecho!B:B,Trecho!BR:BR) -> 857.98 | D13: =IF(C13>B13,"30 MAIOR",IF(B13=C13,"OK","Corrigir")) -> 30 MAIOR | E13: =_xlfn.XLOOKUP(A13&$C$2,Trecho!B:B,Trecho!AD:AD) -> CERVEJARIA CAMAÇARI_10262021- SENDAS DISTRIBUIDORA SA (S4)_30_false | F13: =_xlfn.XLOOKUP(A13&$C$2,Trecho!B:B,Trecho!DH:DH) -> 28687a62-36fa-4ec8-bd49-fbdd0f051bff
A14: BR04xBR04x29022588.0 | B14: =_xlfn.XLOOKUP(A14&$B$2,Trecho!B:B,Trecho!BR:BR) -> 205.37 | C14: =_xlfn.XLOOKUP(A14&$C$2,Trecho!B:B,Trecho!BR:BR) -> 210.7 | D14: =IF(C14>B14,"30 MAIOR",IF(B14=C14,"OK","Corrigir")) -> 30 MAIOR | E14: =_xlfn.XLOOKUP(A14&$C$2,Trecho!B:B,Trecho!AD:AD) -> CERVEJARIA CAMAÇARI_10261944-MERCANTIL RODRIGUES COMERCIAL LTDA(S4)_30_false | F14: =_xlfn.XLOOKUP(A14&$C$2,Trecho!B:B,Trecho!DH:DH) -> 5282d2a6-1c22-4725-a13c-0f34475f3585
... A1110: BR31xBR04xBR8S | B1110: =_xlfn.XLOOKUP(A1110&$B$2,Trecho!B:B,Trecho!BR:BR) -> 2046.12 | C1110: =_xlfn.XLOOKUP(A1110&$C$2,Trecho!B:B,Trecho!BR:BR) -> 2046.12 | D1110: =IF(C1110>B1110,"30 MAIOR",IF(B1110=C1110,"OK","Corrigir")) -> OK | E1110: =_xlfn.XLOOKUP(A1110&$C$2,Trecho!B:B,Trecho!AD:AD) -> CERVEJARIA CAMAÇARI_CD NATAL_30_false | F1110: =_xlfn.XLOOKUP(A1110&$C$2,Trecho!B:B,Trecho!DH:DH) -> 7141d25d-045a-4ac3-8ca0-db134c9555f7

Sheet Trecho
A1: Trecho | C1: Vigencia | D1: Unidade - CNPJ | E1: Unidade - Nome | F1: Unidade SAP | G1: Unidade TMS | H1: Unidade - Promax UNB | I1: Unidade - Regional | J1: Operador - CNPJ | K1: Operador - Nome | L1: Operador - SAP | M1: Operador - TMS | N1: Operador - Promax | O1: Organizacao de Compras | P1: Prazo Pagamento | Q1: Capacidade | R1: Destino | S1: destino SAP | T1: destino TMS | U1: F-MOV | V1: Origem | W1: origem SAP | X1: origem TMS | Y1: cargaHorariaMotoristaPuxadaMensal | Z1: cargaHorariaPorTrajetoMinuto | AA1: cargaHorariaPorTrajetoMinutoLucro | AB1: cargaHorarioTrajetoDia | AC1: cargaHorarioTrajetoMes | AD1: chaveTrecho | AE1: cnpjIda | AF1: cnpjVolta | AG1: consumoDieselAjustado | AH1: custoDaDiaria | AI1: custoDoTr | AJ1: diasMes | AK1: dieselConsumoDieselReaisKM | AL1: dieselConsumoKmL | AM1: fatorMotoristaAjustado | AN1: fatorMotoristaIndicado | AO1: faturamentoDestinoObrigatorio | AP1: freteComCprb | AQ1: freteCtrc | AR1: freteLiquido | AS1: fretePTms | AT1: fretePisCofins | AU1: freteReaisKMDiesel | AV1: freteReaisKMLavagem | AW1: freteReaisKMLucroVariavel | AX1: freteReaisKMManutencaoCarreta | AY1: freteReaisKMManutencaoCavalo | AZ1: freteReaisKMPedagio | BA1: freteReaisKMPneu | BB1: freteReaisKMSalarioVariavel | BC1: freteReaisKMSeguro | BD1: freteReaisViagemDiesel | BE1: freteReaisViagemLavagem | BF1: freteReaisViagemLucroVariavel | BG1: freteReaisViagemManutencaoCarreta | BH1: freteReaisViagemManutencaoCavalo | BI1: freteReaisViagemPedagio | BJ1: freteReaisViagemPneus | BK1: freteReaisViagemSalarioVariavel | BL1: freteReaisViagemSeguro | BM1: frotaNoMunicipio | BN1: gradeCarregamento | BO1: icmsIss | BP1: impostosIcmsIss | BQ1: kmIda | BR1: kmRodado | BS1: kmRodadoMesPorEquipe | BT1: kmRodadoMesPorEquipeLucro | BU1: kmVolta | BV1: lavagemReaisKm | BW1: lucroVariavelReaisKm | BX1: manutencaoCavalo | BY1: manutencaoImplementoReaiskm | BZ1: observacao | CA1: pedagio | CB1: pedagioPorEixoIdaVolta | CC1: pedagioReaisKM | CD1: percentualIcmsIss | CE1: percentualPerdaDescartavel | CF1: percentualPerdaKm | CG1: percentualPerdaRegiao | CH1: pneuCustoPneusCamarasReaisKm | CI1: pneuQuantidadeDePneus | CJ1: pneuValorDeVendaDaCarcaca | CK1: pneuValorMedioDaRecapagem | CL1: pneuValorMedioPneus | CM1: pneuVidautilPneu | CN1: premioProdutividadeFatorMotorista | CO1: premioProdutividadeKmRodado | CP1: premioProdutividadeSalarioVariavel | CQ1: premioProdutividadeSalarioVariavelReaisKm | CR1: previsaoViagens | CS1: regiaoEmpurrada | CT1: seguro | CU1: seguroReaiskm | CV1: tempoInternoDestino | CW1: tempoInternoDestinoLucro | CX1: tempoInternoOrigem | CY1: tempoInternoOrigemLucro | CZ1: tempoRefeicaoMinuto | DA1: tempoTrajetoFabricaCDMinuto | DB1: trechoComDiaria | DC1: trechoComVr | DD1: turnoEmpurrada | DE1: turnosFabrica | DF1: velocidadeMediaKmH | DG1: vidautilAjustadaPneu | DH1: _id
A2: =F2&"x"&W2&"x"&S2 -> BR04xBR04x142200.0 | B2: =F2&"x"&W2&"x"&S2&Q2 -> BR04xBR04x142200.0Pallets: 28 | C2: EMPURRADA_1_9_2026 | D2: 07526557001505_CERV | E2: CAMAÇARI | F2: BR04 | I2: Geo NE | J2: 20618821000799 | K2: OPERALOG | L2: 390268 | N2: 1 | Q2: Pallets: 28 | R2: Unidade: ASA BRANCA | Região: null | S2: 142200.0 | T2: Revenda | U2: FALSE | V2: Unidade: CERVEJARIA CAMAÇARI | Região: NE | W2: BR04 | X2: 421 | Y2: 12500 | Z2: 2806.13 | AA2: 2927.43 | AB2: 1440 | AC2: 36000 | AD2: CERVEJARIA CAMAÇARI_ASA BRANCA_28_false | AE2: 0 | AF2: 0 | AG2: 1.92 | AH2: 115.5 | AI2: 0 | AJ2: 25 | AK2: 3.53 | AL2: 1.92 | AM2: 3 | AN2: 2.88 | AO2: FALSE | AP2: 20209.64 | AQ2: 25306.33 | AR2: 19984.42 | AS2: 20209.64 | AT2: 22269.57 | AU2: 3.53 | AV2: 0.01 | AW2: 0.22 | AX2: 0.1 | AY2: 0.31 | AZ2: 0 | BA2: 0.39 | BB2: 0.46 | BC2: 0 | BD2: 9474.39 | BE2: 19.15 | BF2: 581.07 | BG2: 268.14 | BH2: 819.59 | BI2: 6563.2 | BJ2: 1042.17 | BK2: 1216.7 | BL2: 0 | BM2: FALSE | BN2: 1440 | BO2: 12 | BP2: 3079.56 | BQ2: 1305.63 | BR2: 2686.13 | BS2: 30152.95 | BT2: 28903.54 | BU2: 1380.5 | BV2: 0.01 | BW2: 0.22 | BX2: 0.31 | BY2: 0.1 | CA2: 0 | CB2: 0 | CC2: 0 | CD2: 12 | CE2: 0 | CF2: 0 | CG2: 0 | CH2: 0.39 | CI2: 28.22 | CJ2: 0 | CK2: 437.68 | CL2: 1907.11 | CM2: 202400 | CN2: 3 | CO2: 30152.95 | CP2: 4611.33 | CQ2: 0.46 | CR2: 0.45 | CS2: Região: NE | CT2: 0 | CU2: 0 | CV2: 60 | CW2: 60 | CX2: 60 | CY2: 181.3 | CZ2: 60 | DA2: 2686.13 | DB2: TRUE | DC2: FALSE | DD2: Cargo: MODELO EQUIPE ATIVA ATUAL | DE2: 3 | DF2: 60 | DG2: 202400 | DH2: c1f9a7c0-81c9-43a6-bf14-77e59275d93d
A3: =F3&"x"&W3&"x"&S3 -> BR04xBR04x29021610.0 | B3: =F3&"x"&W3&"x"&S3&Q3 -> BR04xBR04x29021610.0Pallets: 28 | C3: EMPURRADA_1_9_2026 | D3: 07526557001505_CERV | E3: CAMAÇARI | F3: BR04 | I3: Geo NE | J3: 20618821000799 | K3: OPERALOG | L3: 390268 | N3: 1 | Q3: Pallets: 28 | R3: Unidade: 10261249-SENDAS DISTRIBUIDORA SA(S4) | Região: 0 | S3: 29021610.0 | T3: 792071.0 | U3: FALSE | V3: Unidade: CERVEJARIA CAMAÇARI | Região: NE | W3: BR04 | X3: 421 | Y3: 12500 | Z3: 184 | AA3: 305.3 | AB3: 1440 | AC3: 36000 | AD3: CERVEJARIA CAMAÇARI_10261249-SENDAS DISTRIBUIDORA SA(S4)_28_false | AE3: null | AF3: null | AG3: 1.92 | AH3: 0 | AI3: 31 | AJ3: 25 | AK3: 3.53 | AL3: 1.92 | AM3: 3 | AN3: 2.88 | AO3: FALSE | AP3: 1746.9 | AQ3: 2347.51 | AR3: 1726.03 | AS3: 1746.9 | AT3: 1924.96 | AU3: 3.53 | AV3: 0.02 | AW3: 0.95 | AX3: 0.1 | AY3: 0.31 | AZ3: 0 | BA3: 0.39 | BB3: 1.26 | BC3: 0 | BD3: 225.74 | BE3: 1.26 | BF3: 60.6 | BG3: 6.39 | BH3: 19.53 | BI3: 1307.91 | BJ3: 24.83 | BK3: 79.78 | BL3: 0 | BM3: FALSE | BN3: 1440 | BO3: 18 | BP3: 432.22 | BQ3: 32 | BR3: 64 | BS3: 10956.52 | BT3: 6603.34 | BU3: 32 | BV3: 0.02 | BW3: 0.95 | BX3: 0.31 | BY3: 0.1 | BZ3: null | CA3: 0 | CB3: 0 | CC3: 0 | CD3: 18 | CE3: 0 | CF3: 0 | CG3: 0 | CH3: 0.39 | CI3: 28.22 | CJ3: 0 | CK3: 437.68 | CL3: 1907.11 | CM3: 202400 | CN3: 3 | CO3: 10956.52 | CP3: 4611.33 | CQ3: 1.26 | CR3: 6.85 | CS3: Região: NE | CT3: 0 | CU3: 0 | CV3: 60 | CW3: 60 | CX3: 60 | CY3: 181.3 | CZ3: 60 | DA3: 64 | DB3: FALSE | DC3: TRUE | DD3: Cargo: MODELO EQUIPE ATIVA ATUAL | DE3: 3 | DF3: 60 | DG3: 202400 | DH3: 2caf369f-3b1e-4b24-9ff7-79f6c03b0447
A4: =F4&"x"&W4&"x"&S4 -> BR04xBR04x29021490.0 | B4: =F4&"x"&W4&"x"&S4&Q4 -> BR04xBR04x29021490.0Pallets: 28 | C4: EMPURRADA_1_9_2026 | D4: 07526557001505_CERV | E4: CAMAÇARI | F4: BR04 | I4: Geo NE | J4: 20618821000799 | K4: OPERALOG | L4: 390268 | N4: 1 | Q4: Pallets: 28 | R4: Unidade: 10261166-SENDAS DISTRIBUIDORA SA(S4) | Região: 0 | S4: 29021490.0 | T4: 790443.0 | U4: FALSE | V4: Unidade: CERVEJARIA CAMAÇARI | Região: NE | W4: BR04 | X4: 421 | Y4: 12500 | Z4: 1132 | AA4: 1253.3 | AB4: 1440 | AC4: 36000 | AD4: CERVEJARIA CAMAÇARI_10261166-SENDAS DISTRIBUIDORA SA(S4)_28_false | AE4: null | AF4: null | AG4: 1.92 | AH4: 115.5 | AI4: 0 | AJ4: 25 | AK4: 3.53 | AL4: 1.92 | AM4: 3 | AN4: 2.88 | AO4: FALSE | AP4: 7608.29 | AQ4: 10224.13 | AR4: 7517.37 | AS4: 7608.29 | AT4: 8383.79 | AU4: 3.53 | AV4: 0.01 | AW4: 0.25 | AX4: 0.1 | AY4: 0.31 | AZ4: 0 | BA4: 0.39 | BB4: 0.49 | BC4: 0 | BD4: 3569.48 | BE4: 7.73 | BF4: 248.77 | BG4: 101.02 | BH4: 308.78 | BI4: 2398.14 | BJ4: 392.64 | BK4: 490.82 | BL4: 0 | BM4: FALSE | BN4: 1440 | BO4: 18 | BP4: 1882.46 | BQ4: 506 | BR4: 1012 | BS4: 28160.78 | BT4: 25435.25 | BU4: 506 | BV4: 0.01 | BW4: 0.25 | BX4: 0.31 | BY4: 0.1 | BZ4: null | CA4: 0 | CB4: 0 | CC4: 0 | CD4: 18 | CE4: 0 | CF4: 0 | CG4: 0 | CH4: 0.39 | CI4: 28.22 | CJ4: 0 | CK4: 437.68 | CL4: 1907.11 | CM4: 202400 | CN4: 3 | CO4: 28160.78 | CP4: 4611.33 | CQ4: 0.49 | CR4: 1.11 | CS4: Região: NE | CT4: 0 | CU4: 0 | CV4: 60 | CW4: 60 | CX4: 60 | CY4: 181.3 | CZ4: 60 | DA4: 1012 | DB4: TRUE | DC4: FALSE | DD4: Cargo: MODELO EQUIPE ATIVA ATUAL | DE4: 3 | DF4: 60 | DG4: 202400 | DH4: 221c6bb6-1d3f-4866-93a2-1c47598d50d7
A5: =F5&"x"&W5&"x"&S5 -> BR04xBR04x29021355.0 | B5: =F5&"x"&W5&"x"&S5&Q5 -> BR04xBR04x29021355.0Pallets: 28 | C5: EMPURRADA_1_9_2026 | D5: 07526557001505_CERV | E5: CAMAÇARI | F5: BR04 | I5: Geo NE | J5: 20618821000799 | K5: OPERALOG | L5: 390268 | N5: 1 | Q5: Pallets: 28 | R5: Unidade: 10261066-SENDAS DISTRIBUIDORA SA(S4) | Região: 0 | S5: 29021355.0 | T5: 789127.0 | U5: FALSE | V5: Unidade: CERVEJARIA CAMAÇARI | Região: NE | W5: BR04 | X5: 421 | Y5: 12500 | Z5: 1293.41 | AA5: 1414.71 | AB5: 1440 | AC5: 36000 | AD5: CERVEJARIA CAMAÇARI_10261066-SENDAS DISTRIBUIDORA SA(S4)_28_false | AE5: null | AF5: null | AG5: 1.92 | AH5: 115.5 | AI5: 0 | AJ5: 25 | AK5: 3.53 | AL5: 1.92 | AM5: 3 | AN5: 2.88 | AO5: FALSE | AP5: 9504.84 | AQ5: 11901.87 | AR5: 9398.91 | AS5: 9504.84 | AT5: 10473.65 | AU5: 3.53 | AV5: 0.01 | AW5: 0.24 | AX5: 0.1 | AY5: 0.31 | AZ5: 0 | BA5: 0.39 | BB5: 0.48 | BC5: 0 | BD5: 4138.8 | BE5: 8.83 | BF5: 280.81 | BG5: 117.14 | BH5: 358.03 | BI5: 3479.25 | BJ5: 455.26 | BK5: 560.8 | BL5: 0 | BM5: FALSE | BN5: 1440 | BO5: 12 | BP5: 1448.36 | BQ5: 595.06 | BR5: 1173.41 | BS5: 28577.49 | BT5: 26127.2 | BU5: 578.35 | BV5: 0.01 | BW5: 0.24 | BX5: 0.31 | BY5: 0.1 | BZ5: null | CA5: 0 | CB5: 0 | CC5: 0 | CD5: 12 | CE5: 0 | CF5: 0 | CG5: 0 | CH5: 0.39 | CI5: 28.22 | CJ5: 0 | CK5: 437.68 | CL5: 1907.11 | CM5: 202400 | CN5: 3 | CO5: 28577.49 | CP5: 4611.33 | CQ5: 0.48 | CR5: 0.97 | CS5: Região: NE | CT5: 0 | CU5: 0 | CV5: 60 | CW5: 60 | CX5: 60 | CY5: 181.3 | CZ5: 60 | DA5: 1173.41 | DB5: TRUE | DC5: FALSE | DD5: Cargo: MODELO EQUIPE ATIVA ATUAL | DE5: 3 | DF5: 60 | DG5: 202400 | DH5: a43e452c-0095-4512-86bd-f48529a503bc
A6: =F6&"x"&W6&"x"&S6 -> BR04xBR04x29021307.0 | B6: =F6&"x"&W6&"x"&S6&Q6 -> BR04xBR04x29021307.0Pallets: 28 | C6: EMPURRADA_1_9_2026 | D6: 07526557001505_CERV | E6: CAMAÇARI | F6: BR04 | I6: Geo NE | J6: 20618821000799 | K6: OPERALOG | L6: 390268 | N6: 1 | Q6: Pallets: 28 | R6: Unidade: 10261027-SENDAS DISTRIBUIDORA SA(S4) | Região: 0 | S6: 29021307.0 | T6: 788759.0 | U6: FALSE | V6: Unidade: CERVEJARIA CAMAÇARI | Região: NE | W6: BR04 | X6: 421 | Y6: 12500 | Z6: 1198 | AA6: 1319.3 | AB6: 1440 | AC6: 36000 | AD6: CERVEJARIA CAMAÇARI_10261027-SENDAS DISTRIBUIDORA SA(S4)_28_false | AE6: null | AF6: null | AG6: 1.92 | AH6: 115.5 | AI6: 0 | AJ6: 25 | AK6: 3.53 | AL6: 1.92 | AM6: 3 | AN6: 2.88 | AO6: FALSE | AP6: 7899.97 | AQ6: 10616.09 | AR6: 7805.56 | AS6: 7899.97 | AT6: 8705.2 | AU6: 3.53 | AV6: 0.01 | AW6: 0.24 | AX6: 0.1 | AY6: 0.31 | AZ6: 0 | BA6: 0.39 | BB6: 0.49 | BC6: 0 | BD6: 3802.27 | BE6: 8.18 | BF6: 261.87 | BG6: 107.61 | BH6: 328.92 | BI6: 2359.04 | BJ6: 418.24 | BK6: 519.43 | BL6: 0 | BM6: FALSE | BN6: 1440 | BO6: 18 | BP6: 1954.63 | BQ6: 539 | BR6: 1078 | BS6: 28344.74 | BT6: 25738.65 | BU6: 539 | BV6: 0.01 | BW6: 0.24 | BX6: 0.31 | BY6: 0.1 | BZ6: null | CA6: 0 | CB6: 0 | CC6: 0 | CD6: 18 | CE6: 0 | CF6: 0 | CG6: 0 | CH6: 0.39 | CI6: 28.22 | CJ6: 0 | CK6: 437.68 | CL6: 1907.11 | CM6: 202400 | CN6: 3 | CO6: 28344.74 | CP6: 4611.33 | CQ6: 0.49 | CR6: 1.05 | CS6: Região: NE | CT6: 0 | CU6: 0 | CV6: 60 | CW6: 60 | CX6: 60 | CY6: 181.3 | CZ6: 60 | DA6: 1078 | DB6: TRUE | DC6: FALSE | DD6: Cargo: MODELO EQUIPE ATIVA ATUAL | DE6: 3 | DF6: 60 | DG6: 202400 | DH6: 70b668fb-771c-4cae-82f0-3a25d580d775
A7: =F7&"x"&W7&"x"&S7 -> BR04xBR04x29021312.0 | B7: =F7&"x"&W7&"x"&S7&Q7 -> BR04xBR04x29021312.0Pallets: 28 | C7: EMPURRADA_1_9_2026 | D7: 07526557001505_CERV | E7: CAMAÇARI | F7: BR04 | I7: Geo NE | J7: 20618821000799 | K7: OPERALOG | L7: 390268 | N7: 1 | Q7: Pallets: 28 | R7: Unidade: 10261032-SENDAS DISTRIBUIDORA SA(S4) | Região: 0 | S7: 29021312.0 | T7: 788732.0 | U7: FALSE | V7: Unidade: CERVEJARIA CAMAÇARI | Região: NE | W7: BR04 | X7: 421 | Y7: 12500 | Z7: 1682.25 | AA7: 1803.55 | AB7: 1440 | AC7: 36000 | AD7: CERVEJARIA CAMAÇARI_10261032-SENDAS DISTRIBUIDORA SA(S4)_28_false | AE7: null | AF7: null | AG7: 1.92 | AH7: 115.5 | AI7: 0 | AJ7: 25 | AK7: 3.53 | AL7: 1.92 | AM7: 3 | AN7: 2.88 | AO7: FALSE | AP7: 12086.48 | AQ7: 15134.59 | AR7: 11951.79 | AS7: 12086.48 | AT7: 13318.44 | AU7: 3.53 | AV7: 0.01 | AW7: 0.23 | AX7: 0.1 | AY7: 0.31 | AZ7: 0 | BA7: 0.39 | BB7: 0.47 | BC7: 0 | BD7: 5510.3 | BE7: 11.48 | BF7: 357.99 | BG7: 155.95 | BH7: 476.67 | BI7: 4103.87 | BJ7: 606.12 | BK7: 729.4 | BL7: 0 | BM7: FALSE | BN7: 1440 | BO7: 12 | BP7: 1841.75 | BQ7: 784.43 | BR7: 1562.25 | BS7: 29253.01 | BT7: 27285.56 | BU7: 777.82 | BV7: 0.01 | BW7: 0.23 | BX7: 0.31 | BY7: 0.1 | BZ7: null | CA7: 0 | CB7: 0 | CC7: 0 | CD7: 12 | CE7: 0 | CF7: 0 | CG7: 0 | CH7: 0.39 | CI7: 28.22 | CJ7: 0 | CK7: 437.68 | CL7: 1907.11 | CM7: 202400 | CN7: 3 | CO7: 29253.01 | CP7: 4611.33 | CQ7: 0.47 | CR7: 0.75 | CS7: Região: NE | CT7: 0 | CU7: 0 | CV7: 60 | CW7: 60 | CX7: 60 | CY7: 181.3 | CZ7: 60 | DA7: 1562.25 | DB7: TRUE | DC7: FALSE | DD7: Cargo: MODELO EQUIPE ATIVA ATUAL | DE7: 3 | DF7: 60 | DG7: 202400 | DH7: 3f605636-6d2e-4eb9-af1d-1c0636749866
A8: =F8&"x"&W8&"x"&S8 -> BR04xBR04x29022096.0 | B8: =F8&"x"&W8&"x"&S8&Q8 -> BR04xBR04x29022096.0Pallets: 28 | C8: EMPURRADA_1_9_2026 | D8: 07526557001505_CERV | E8: CAMAÇARI | F8: BR04 | I8: Geo NE | J8: 20618821000799 | K8: OPERALOG | L8: 390268 | N8: 1 | Q8: Pallets: 28 | R8: Unidade: 10261587-ATACADAO S A(S4) | Região: 0 | S8: 29022096.0 | T8: 796239.0 | U8: FALSE | V8: Unidade: CERVEJARIA CAMAÇARI | Região: NE | W8: BR04 | X8: 421 | Y8: 12500 | Z8: 319.17 | AA8: 440.47 | AB8: 1440 | AC8: 36000 | AD8: CERVEJARIA CAMAÇARI_10261587-ATACADAO S A(S4)_28_false | AE8: null | AF8: null | AG8: 1.92 | AH8: 0 | AI8: 31 | AJ8: 25 | AK8: 3.53 | AL8: 1.92 | AM8: 3 | AN8: 2.88 | AO8: FALSE | AP8: 2556.83 | AQ8: 3435.91 | AR8: 2526.28 | AS8: 2556.83 | AT8: 2817.45 | AU8: 3.53 | AV8: 0.01 | AW8: 0.44 | AX8: 0.1 | AY8: 0.31 | AZ8: 0 | BA8: 0.39 | BB8: 0.7 | BC8: 0 | BD8: 702.5 | BE8: 2.18 | BF8: 87.43 | BG8: 19.88 | BH8: 60.77 | BI8: 1437.85 | BJ8: 77.27 | BK8: 138.39 | BL8: 0 | BM8: FALSE | BN8: 1440 | BO8: 18 | BP8: 632.62 | BQ8: 100.55 | BR8: 199.17 | BS8: 19656.78 | BT8: 14243.55 | BU8: 98.62 | BV8: 0.01 | BW8: 0.44 | BX8: 0.31 | BY8: 0.1 | BZ8: null | CA8: 0 | CB8: 0 | CC8: 0 | CD8: 18 | CE8: 0 | CF8: 0 | CG8: 0 | CH8: 0.39 | CI8: 28.22 | CJ8: 0 | CK8: 437.68 | CL8: 1907.11 | CM8: 202400 | CN8: 3 | CO8: 19656.78 | CP8: 4611.33 | CQ8: 0.7 | CR8: 3.95 | CS8: Região: NE | CT8: 0 | CU8: 0 | CV8: 60 | CW8: 60 | CX8: 60 | CY8: 181.3 | CZ8: 60 | DA8: 199.17 | DB8: FALSE | DC8: TRUE | DD8: Cargo: MODELO EQUIPE ATIVA ATUAL | DE8: 3 | DF8: 60 | DG8: 202400 | DH8: 3475189a-5709-40ca-bcb8-39cecc1b8c4d
A9: =F9&"x"&W9&"x"&S9 -> BR04xBR04x29021848.0 | B9: =F9&"x"&W9&"x"&S9&Q9 -> BR04xBR04x29021848.0Pallets: 28 | C9: EMPURRADA_1_9_2026 | D9: 07526557001505_CERV | E9: CAMAÇARI | F9: BR04 | I9: Geo NE | J9: 20618821000799 | K9: OPERALOG | L9: 390268 | N9: 1 | Q9: Pallets: 28 | R9: Unidade: 10261402-SUPERMERCADO COMETA LTDA(S4) | Região: 0.0 | S9: 29021848.0 | T9: 794333.0 | U9: FALSE | V9: Unidade: CERVEJARIA CAMAÇARI | Região: NE | W9: BR04 | X9: 421 | Y9: 12500 | Z9: 2462.78 | AA9: 2584.08 | AB9: 1440 | AC9: 36000 | AD9: CERVEJARIA CAMAÇARI_10261402-SUPERMERCADO COMETA LTDA(S4)_28_false | AE9: null | AF9: null | AG9: 1.92 | AH9: 115.5 | AI9: 0 | AJ9: 25 | AK9: 3.53 | AL9: 1.92 | AM9: 3 | AN9: 2.88 | AO9: FALSE | AP9: 17362.78 | AQ9: 21741.53 | AR9: 17169.29 | AS9: 17362.78 | AT9: 19132.54 | AU9: 3.53 | AV9: 0.01 | AW9: 0.22 | AX9: 0.1 | AY9: 0.31 | AZ9: 0 | BA9: 0.39 | BB9: 0.46 | BC9: 0 | BD9: 8263.35 | BE9: 16.81 | BF9: 512.92 | BG9: 233.87 | BH9: 714.82 | BI9: 5450.75 | BJ9: 908.96 | BK9: 1067.82 | BL9: 0 | BM9: FALSE | BN9: 1440 | BO9: 12 | BP9: 2645.76 | BQ9: 1171.49 | BR9: 2342.78 | BS9: 29965.15 | BT9: 28558.55 | BU9: 1171.29 | BV9: 0.01 | BW9: 0.22 | BX9: 0.31 | BY9: 0.1 | BZ9: null | CA9: 0 | CB9: 0 | CC9: 0 | CD9: 12 | CE9: 0 | CF9: 0 | CG9: 0 | CH9: 0.39 | CI9: 28.22 | CJ9: 0 | CK9: 437.68 | CL9: 1907.11 | CM9: 202400 | CN9: 3 | CO9: 29965.15 | CP9: 4611.33 | CQ9: 0.46 | CR9: 0.51 | CS9: Região: NE | CT9: 0 | CU9: 0 | CV9: 60 | CW9: 60 | CX9: 60 | CY9: 181.3 | CZ9: 60 | DA9: 2342.78 | DB9: TRUE | DC9: FALSE | DD9: Cargo: MODELO EQUIPE ATIVA ATUAL | DE9: 3 | DF9: 60 | DG9: 202400 | DH9: 584132c3-e1a3-4ad7-a454-77363c5b29ee
A10: =F10&"x"&W10&"x"&S10 -> BR04xBR04x29021611.0 | B10: =F10&"x"&W10&"x"&S10&Q10 -> BR04xBR04x29021611.0Pallets: 28 | C10: EMPURRADA_1_9_2026 | D10: 07526557001505_CERV | E10: CAMAÇARI | F10: BR04 | I10: Geo NE | J10: 20618821000799 | K10: OPERALOG | L10: 390268 | N10: 1 | Q10: Pallets: 28 | R10: Unidade: 10261250-SENDAS DISTRIBUIDORA SA(S4) | Região: 0 | S10: 29021611.0 | T10: 792080.0 | U10: FALSE | V10: Unidade: CERVEJARIA CAMAÇARI | Região: NE | W10: BR04 | X10: 421 | Y10: 12500 | Z10: 229 | AA10: 350.3 | AB10: 1440 | AC10: 36000 | AD10: CERVEJARIA CAMAÇARI_10261250-SENDAS DISTRIBUIDORA SA(S4)_28_false | AE10: null | AF10: null | AG10: 1.92 | AH10: 0 | AI10: 31 | AJ10: 25 | AK10: 3.53 | AL10: 1.92 | AM10: 3 | AN10: 2.88 | AO10: FALSE | AP10: 1936.81 | AQ10: 2602.71 | AR10: 1913.66 | AS10: 1936.81 | AT10: 2134.22 | AU10: 3.53 | AV10: 0.01 | AW10: 0.64 | AX10: 0.1 | AY10: 0.31 | AZ10: 0 | BA10: 0.39 | BB10: 0.92 | BC10: 0 | BD10: 384.46 | BE10: 1.56 | BF10: 69.53 | BG10: 10.88 | BH10: 33.26 | BI10: 1272.39 | BJ10: 42.29 | BK10: 99.29 | BL10: 0 | BM10: FALSE | BN10: 1440 | BO10: 18 | BP10: 479.21 | BQ10: 55 | BR10: 109 | BS10: 14993.45 | BT10: 9801.6 | BU10: 54 | BV10: 0.01 | BW10: 0.64 | BX10: 0.31 | BY10: 0.1 | BZ10: null | CA10: 0 | CB10: 0 | CC10: 0 | CD10: 18 | CE10: 0 | CF10: 0 | CG10: 0 | CH10: 0.39 | CI10: 28.22 | CJ10: 0 | CK10: 437.68 | CL10: 1907.11 | CM10: 202400 | CN10: 3 | CO10: 14993.45 | CP10: 4611.33 | CQ10: 0.92 | CR10: 5.5 | CS10: Região: NE | CT10: 0 | CU10: 0 | CV10: 60 | CW10: 60 | CX10: 60 | CY10: 181.3 | CZ10: 60 | DA10: 109 | DB10: FALSE | DC10: TRUE | DD10: Cargo: MODELO EQUIPE ATIVA ATUAL | DE10: 3 | DF10: 60 | DG10: 202400 | DH10: 3ced02f2-aa19-4e25-8eb2-2f3828510e9f
A11: =F11&"x"&W11&"x"&S11 -> BR04xBR04x29023180.0 | B11: =F11&"x"&W11&"x"&S11&Q11 -> BR04xBR04x29023180.0Pallets: 28 | C11: EMPURRADA_1_9_2026 | D11: 07526557001505_CERV | E11: CAMAÇARI | F11: BR04 | I11: Geo NE | J11: 20618821000799 | K11: OPERALOG | L11: 390268 | N11: 1 | Q11: Pallets: 28 | R11: Unidade: 10262331-ATACADAO S A(S4) | Região: 0 | S11: 29023180.0 | T11: 816523.0 | U11: FALSE | V11: Unidade: CERVEJARIA CAMAÇARI | Região: NE | W11: BR04 | X11: 421 | Y11: 12500 | Z11: 1678.89 | AA11: 1800.19 | AB11: 1440 | AC11: 36000 | AD11: CERVEJARIA CAMAÇARI_10262331-ATACADAO S A(S4)_28_false | AE11: null | AF11: null | AG11: 1.92 | AH11: 115.5 | AI11: 0 | AJ11: 25 | AK11: 3.53 | AL11: 1.92 | AM11: 3 | AN11: 2.88 | AO11: FALSE | AP11: 12289.96 | AQ11: 15389.38 | AR11: 12153 | AS11: 12289.96 | AT11: 13542.66 | AU11: 3.53 | AV11: 0.01 | AW11: 0.23 | AX11: 0.1 | AY11: 0.31 | AZ11: 0 | BA11: 0.39 | BB11: 0.47 | BC11: 0 | BD11: 5498.45 | BE11: 11.46 | BF11: 357.32 | BG11: 155.62 | BH11: 475.65 | BI11: 4321.75 | BJ11: 604.82 | BK11: 727.94 | BL11: 0 | BM11: FALSE | BN11: 1440 | BO11: 12 | BP11: 1872.76 | BQ11: 782.05 | BR11: 1558.89 | BS11: 29248.51 | BT11: 27277.7 | BU11: 776.84 | BV11: 0.01 | BW11: 0.23 | BX11: 0.31 | BY11: 0.1 | BZ11: null | CA11: 0 | CB11: 0 | CC11: 0 | CD11: 12 | CE11: 0 | CF11: 0 | CG11: 0 | CH11: 0.39 | CI11: 28.22 | CJ11: 0 | CK11: 437.68 | CL11: 1907.11 | CM11: 202400 | CN11: 3 | CO11: 29248.51 | CP11: 4611.33 | CQ11: 0.47 | CR11: 0.75 | CS11: Região: NE | CT11: 0 | CU11: 0 | CV11: 60 | CW11: 60 | CX11: 60 | CY11: 181.3 | CZ11: 60 | DA11: 1558.89 | DB11: TRUE | DC11: FALSE | DD11: Cargo: MODELO EQUIPE ATIVA ATUAL | DE11: 3 | DF11: 60 | DG11: 202400 | DH11: bb3b7946-a6ed-4607-8ba5-b223db54abe3
A12: =F12&"x"&W12&"x"&S12 -> BR04xBR04x29022977.0 | B12: =F12&"x"&W12&"x"&S12&Q12 -> BR04xBR04x29022977.0Pallets: 28 | C12: EMPURRADA_1_9_2026 | D12: 07526557001505_CERV | E12: CAMAÇARI | F12: BR04 | I12: Geo NE | J12: 20618821000799 | K12: OPERALOG | L12: 390268 | N12: 1 | Q12: Pallets: 28 | R12: Unidade: 10262178-DISTCARNES DISTRIBUIDORA CARNES(S4) | Região: 0 | S12: 29022977.0 | T12: 814237.0 | U12: FALSE | V12: Unidade: CERVEJARIA CAMAÇARI | Região: NE | W12: BR04 | X12: 421 | Y12: 12500 | Z12: 1679.85 | AA12: 1801.15 | AB12: 1440 | AC12: 36000 | AD12: CERVEJARIA CAMAÇARI_10262178-DISTCARNES DISTRIBUIDORA CARNES(S4)_28_false | AE12: null | AF12: null | AG12: 1.92 | AH12: 115.5 | AI12: 0 | AJ12: 25 | AK12: 3.53 | AL12: 1.92 | AM12: 3 | AN12: 2.88 | AO12: FALSE | AP12: 12406.3 | AQ12: 15535.07 | AR12: 12268.05 | AS12: 12406.3 | AT12: 13670.86 | AU12: 3.53 | AV12: 0.01 | AW12: 0.23 | AX12: 0.1 | AY12: 0.31 | AZ12: 0 | BA12: 0.39 | BB12: 0.47 | BC12: 0 | BD12: 5501.83 | BE12: 11.47 | BF12: 357.51 | BG12: 155.71 | BH12: 475.94 | BI12: 4432.03 | BJ12: 605.19 | BK12: 728.36 | BL12: 0 | BM12: FALSE | BN12: 1440 | BO12: 12 | BP12: 1890.48 | BQ12: 782.03 | BR12: 1559.85 | BS12: 29249.8 | BT12: 27279.95 | BU12: 777.82 | BV12: 0.01 | BW12: 0.23 | BX12: 0.31 | BY12: 0.1 | BZ12: null | CA12: 0 | CB12: 0 | CC12: 0 | CD12: 12 | CE12: 0 | CF12: 0 | CG12: 0 | CH12: 0.39 | CI12: 28.22 | CJ12: 0 | CK12: 437.68 | CL12: 1907.11 | CM12: 202400 | CN12: 3 | CO12: 29249.8 | CP12: 4611.33 | CQ12: 0.47 | CR12: 0.75 | CS12: Região: NE | CT12: 0 | CU12: 0 | CV12: 60 | CW12: 60 | CX12: 60 | CY12: 181.3 | CZ12: 60 | DA12: 1559.85 | DB12: TRUE | DC12: FALSE | DD12: Cargo: MODELO EQUIPE ATIVA ATUAL | DE12: 3 | DF12: 60 | DG12: 202400 | DH12: b2a27fe1-660c-4869-9b30-f4f00d952ce6
A13: =F13&"x"&W13&"x"&S13 -> BR04xBR04x29022696.0 | B13: =F13&"x"&W13&"x"&S13&Q13 -> BR04xBR04x29022696.0Pallets: 28 | C13: EMPURRADA_1_9_2026 | D13: 07526557001505_CERV | E13: CAMAÇARI | F13: BR04 | I13: Geo NE | J13: 20618821000799 | K13: OPERALOG | L13: 390268 | N13: 1 | Q13: Pallets: 28 | R13: Unidade: 10262021-SENDAS DISTRIBUIDORA SA(S4) | Região: 0 | S13: 29022696.0 | T13: 811653.0 | U13: FALSE | V13: Unidade: CERVEJARIA CAMAÇARI | Região: NE | W13: BR04 | X13: 421 | Y13: 12500 | Z13: 974 | AA13: 1095.3 | AB13: 1440 | AC13: 36000 | AD13: CERVEJARIA CAMAÇARI_10262021-SENDAS DISTRIBUIDORA SA(S4)_28_false | AE13: null | AF13: null | AG13: 1.92 | AH13: 115.5 | AI13: 0 | AJ13: 25 | AK13: 3.53 | AL13: 1.92 | AM13: 3 | AN13: 2.88 | AO13: FALSE | AP13: 6544.48 | AQ13: 8794.57 | AR13: 6466.27 | AS13: 6544.48 | AT13: 7211.54 | AU13: 3.53 | AV13: 0.01 | AW13: 0.25 | AX13: 0.1 | AY13: 0.31 | AZ13: 0 | BA13: 0.39 | BB13: 0.5 | BC13: 0 | BD13: 3012.19 | BE13: 6.65 | BF13: 217.41 | BG13: 85.25 | BH13: 260.57 | BI13: 2130.56 | BJ13: 331.34 | BK13: 422.31 | BL13: 0 | BM13: FALSE | BN13: 1440 | BO13: 18 | BP13: 1619.25 | BQ13: 427 | BR13: 854 | BS13: 27619.1 | BT13: 24560.39 | BU13: 427 | BV13: 0.01 | BW13: 0.25 | BX13: 0.31 | BY13: 0.1 | BZ13: null | CA13: 0 | CB13: 0 | CC13: 0 | CD13: 18 | CE13: 0 | CF13: 0 | CG13: 0 | CH13: 0.39 | CI13: 28.22 | CJ13: 0 | CK13: 437.68 | CL13: 1907.11 | CM13: 202400 | CN13: 3 | CO13: 27619.1 | CP13: 4611.33 | CQ13: 0.5 | CR13: 1.29 | CS13: Região: NE | CT13: 0 | CU13: 0 | CV13: 60 | CW13: 60 | CX13: 60 | CY13: 181.3 | CZ13: 60 | DA13: 854 | DB13: TRUE | DC13: FALSE | DD13: Cargo: MODELO EQUIPE ATIVA ATUAL | DE13: 3 | DF13: 60 | DG13: 202400 | DH13: f4852988-b6a1-44f8-ad2b-f7db429b1b67
A14: =F14&"x"&W14&"x"&S14 -> BR04xBR04x29022588.0 | B14: =F14&"x"&W14&"x"&S14&Q14 -> BR04xBR04x29022588.0Pallets: 28 | C14: EMPURRADA_1_9_2026 | D14: 07526557001505_CERV | E14: CAMAÇARI | F14: BR04 | I14: Geo NE | J14: 20618821000799 | K14: OPERALOG | L14: 390268 | N14: 1 | Q14: Pallets: 28 | R14: Unidade: 10261944-MERCANTIL RODRIGUES COMERCIAL LTDA(S4) | Região: 0 | S14: 29022588.0 | T14: 810614.0 | U14: FALSE | V14: Unidade: CERVEJARIA CAMAÇARI | Região: NE | W14: BR04 | X14: 421 | Y14: 12500 | Z14: 325.37 | AA14: 446.67 | AB14: 1440 | AC14: 36000 | AD14: CERVEJARIA CAMAÇARI_10261944-MERCANTIL RODRIGUES COMERCIAL LTDA(S4)_28_false | AE14: null | AF14: null | AG14: 1.92 | AH14: 0 | AI14: 31 | AJ14: 25 | AK14: 3.53 | AL14: 1.92 | AM14: 3 | AN14: 2.88 | AO14: FALSE | AP14: 2579.82 | AQ14: 3466.8 | AR14: 2548.99 | AS14: 2579.82 | AT14: 2842.78 | AU14: 3.53 | AV14: 0.01 | AW14: 0.43 | AX14: 0.1 | AY14: 0.31 | AZ14: 0 | BA14: 0.39 | BB14: 0.7 | BC14: 0 | BD14: 724.37 | BE14: 2.22 | BF14: 88.66 | BG14: 20.5 | BH14: 62.66 | BI14: 1429.82 | BJ14: 79.68 | BK14: 141.08 | BL14: 0 | BM14: FALSE | BN14: 1440 | BO14: 18 | BP14: 638.31 | BQ14: 104.13 | BR14: 205.37 | BS14: 19882.46 | BT14: 14483.07 | BU14: 101.24 | BV14: 0.01 | BW14: 0.43 | BX14: 0.31 | BY14: 0.1 | BZ14: null | CA14: 0 | CB14: 0 | CC14: 0 | CD14: 18 | CE14: 0 | CF14: 0 | CG14: 0 | CH14: 0.39 | CI14: 28.22 | CJ14: 0 | CK14: 437.68 | CL14: 1907.11 | CM14: 202400 | CN14: 3 | CO14: 19882.46 | CP14: 4611.33 | CQ14: 0.7 | CR14: 3.87 | CS14: Região: NE | CT14: 0 | CU14: 0 | CV14: 60 | CW14: 60 | CX14: 60 | CY14: 181.3 | CZ14: 60 | DA14: 205.37 | DB14: FALSE | DC14: TRUE | DD14: Cargo: MODELO EQUIPE ATIVA ATUAL | DE14: 3 | DF14: 60 | DG14: 202400 | DH14: 0a75e8ab-21df-458f-97f2-f63e1fb1b05d
... A177: =F177&"x"&W177&"x"&S177 -> BR04xBR04x487570.0 | B177: =F177&"x"&W177&"x"&S177&Q177 -> BR04xBR04x487570.0Pallets: 28 | C177: EMPURRADA_1_9_2026 | D177: 07526557001505_CERV | E177: CAMAÇARI | F177: BR04 | I177: Geo NE | J177: 20618821000799 | K177: OPERALOG | L177: 390268 | N177: 1 | Q177: Pallets: 28 | R177: Unidade: 487570-PAU BRASIL/SOUSA(PB) | S177: 487570.0 | T177: Revenda | U177: FALSE | V177: Unidade: CERVEJARIA CAMAÇARI | Região: NE | W177: BR04 | X177: 421 | Y177: 12500 | Z177: 1738 | AA177: 1859.3 | AB177: 1440 | AC177: 36000 | AD177: CERVEJARIA CAMAÇARI_487570-PAU BRASIL/SOUSA(PB)_28_false | AE177: null | AF177: null | AG177: 1.92 | AH177: 115.5 | AI177: 0 | AJ177: 25 | AK177: 3.53 | AL177: 1.92 | AM177: 3 | AN177: 2.88 | AO177: FALSE | AP177: 12421.61 | AQ177: 15554.23 | AR177: 12283.18 | AS177: 12421.61 | AT177: 13687.72 | AU177: 3.53 | AV177: 0.01 | AW177: 0.23 | AX177: 0.1 | AY177: 0.31 | AZ177: 0 | BA177: 0.39 | BB177: 0.47 | BC177: 0 | BD177: 5706.94 | BE177: 11.86 | BF177: 369.05 | BG177: 161.52 | BH177: 493.68 | BI177: 4158.81 | BJ177: 627.75 | BK177: 753.57 | BL177: 0 | BM177: FALSE | BN177: 1440 | BO177: 12 | BP177: 1892.82 | BQ177: 809 | BR177: 1618 | BS177: 29325.09 | BT177: 27411.93 | BU177: 809 | BV177: 0.01 | BW177: 0.23 | BX177: 0.31 | BY177: 0.1 | BZ177: null | CA177: 0 | CB177: 0 | CC177: 0 | CD177: 12 | CE177: 0 | CF177: 0 | CG177: 0 | CH177: 0.39 | CI177: 28.22 | CJ177: 0 | CK177: 437.68 | CL177: 1907.11 | CM177: 202400 | CN177: 3 | CO177: 29325.09 | CP177: 4611.33 | CQ177: 0.47 | CR177: 0.72 | CS177: Região: NE | CT177: 0 | CU177: 0 | CV177: 60 | CW177: 60 | CX177: 60 | CY177: 181.3 | CZ177: 60 | DA177: 1618 | DB177: TRUE | DC177: FALSE | DD177: Cargo: MODELO EQUIPE ATIVA ATUAL | DE177: 3 | DF177: 60 | DG177: 202400 | DH177: be4e99ec-96e9-4473-a136-8c65fff875de
A178: =F178&"x"&W178&"x"&S178 -> BR04xBR04xBR28 | B178: =F178&"x"&W178&"x"&S178&Q178 -> BR04xBR04xBR28Pallets: 28 | C178: EMPURRADA_1_9_2026 | D178: 07526557001505_CERV | E178: CAMAÇARI | F178: BR04 | I178: Geo NE | J178: 20618821000799 | K178: OPERALOG | L178: 390268 | N178: 1 | Q178: Pallets: 28 | R178: Unidade: CDR BELEM | S178: BR28 | T178: 433.0 | U178: FALSE | V178: Unidade: CERVEJARIA CAMAÇARI | Região: NE | W178: BR04 | X178: 421 | Y178: 12500 | Z178: 4316 | AA178: 4423.53 | AB178: 1440 | AC178: 36000 | AD178: CERVEJARIA CAMAÇARI_CDR BELEM_28_false | AG178: 1.92 | AH178: 115.5 | AI178: 0 | AJ178: 25 | AK178: 3.53 | AL178: 1.92 | AM178: 3 | AN178: 2.88 | AO178: FALSE | AP178: 28902.54 | AQ178: 36191.51 | AR178: 28580.45 | AS178: 28902.54 | AT178: 31848.53 | AU178: 3.53 | AV178: 0.01 | AW178: 0.21 | AX178: 0.1 | AY178: 0.31 | AZ178: 0 | BA178: 0.39 | BB178: 0.45 | BC178: 0 | BD178: 14799.94 | BE178: 29.46 | BF178: 878.03 | BG178: 418.87 | BH178: 1280.27 | BI178: 7791.84 | BJ178: 1627.97 | BK178: 1754.07 | BL178: 0 | BM178: FALSE | BN178: 1440 | BO178: 12 | BP178: 4404.2 | BQ178: 2099 | BR178: 4196 | BS178: 30624.19 | BT178: 29879.76 | BU178: 2097 | BV178: 0.01 | BW178: 0.21 | BX178: 0.31 | BY178: 0.1 | CA178: 0 | CB178: 0 | CC178: 0 | CD178: 12 | CE178: 0 | CF178: 0 | CG178: 0 | CH178: 0.39 | CI178: 28.22 | CJ178: 0 | CK178: 437.68 | CL178: 1907.11 | CM178: 202400 | CN178: 3 | CO178: 30624.19 | CP178: 4611.33 | CQ178: 0.45 | CR178: 0.29 | CS178: Região: NE | CT178: 0 | CU178: 0 | CV178: 60 | CW178: 56.28 | CX178: 60 | CY178: 171.25 | CZ178: 60 | DA178: 4196 | DB178: TRUE | DC178: FALSE | DD178: Cargo: MODELO EQUIPE ATIVA ATUAL | DE178: 3 | DF178: 60 | DG178: 202400 | DH178: 5405cc4a-9799-4b55-8b20-a42d11ec347b
A179: =F179&"x"&W179&"x"&S179 -> BR04xBR17xBR5D | B179: =F179&"x"&W179&"x"&S179&Q179 -> BR04xBR17xBR5DPallets: 28 | C179: EMPURRADA_1_9_2026 | D179: 07526557001505_CERV | E179: CAMAÇARI | F179: BR04 | I179: Geo NE | J179: 20618821000799 | K179: OPERALOG | L179: 390268 | N179: 1 | Q179: Pallets: 28 | R179: Unidade: CDR BAHIA | Região: NE | S179: BR5D | T179: 505 | U179: FALSE | V179: Unidade: CERVEJARIA JUATUBA | Região: MG | W179: BR17 | X179: 140 | Y179: 12500 | Z179: 2973.8 | AA179: 3142.03 | AB179: 1440 | AC179: 36000 | AD179: CERVEJARIA JUATUBA_CDR BAHIA_28_false | AG179: 1.92 | AH179: 115.5 | AI179: 0 | AJ179: 25 | AK179: 3.53 | AL179: 1.92 | AM179: 3 | AN179: 2.88 | AO179: FALSE | AP179: 17815.43 | AQ179: 22308.32 | AR179: 17616.89 | AS179: 17815.43 | AT179: 19631.32 | AU179: 3.53 | AV179: 0.01 | AW179: 0.22 | AX179: 0.1 | AY179: 0.31 | AZ179: 0 | BA179: 0.39 | BB179: 0.46 | BC179: 0 | BD179: 10065.79 | BE179: 20.3 | BF179: 623.67 | BG179: 284.88 | BH179: 870.75 | BI179: 3435.71 | BJ179: 1107.22 | BK179: 1208.58 | BL179: 0 | BM179: FALSE | BN179: 1440 | BO179: 12 | BP179: 2714.73 | BQ179: 1428.8 | BR179: 2853.8 | BS179: 30228.9 | BT179: 28610.39 | BU179: 1425 | BV179: 0.01 | BW179: 0.22 | BX179: 0.31 | BY179: 0.1 | CA179: 0 | CB179: 0 | CC179: 0 | CD179: 12 | CE179: 0 | CF179: 0 | CG179: 0 | CH179: 0.39 | CI179: 28.22 | CJ179: 0 | CK179: 437.68 | CL179: 1907.11 | CM179: 202400 | CN179: 3 | CO179: 30228.9 | CP179: 4611.33 | CQ179: 0.46 | CR179: 0.42 | CS179: Região: NE | CT179: 0 | CU179: 0 | CV179: 60 | CW179: 183.71 | CX179: 60 | CY179: 104.52 | CZ179: 60 | DA179: 2853.8 | DB179: TRUE | DC179: FALSE | DD179: Cargo: MODELO EQUIPE ATIVA ATUAL | DE179: 3 | DF179: 60 | DG179: 202400 | DH179: 158d5304-2abf-4e3f-aa73-37cadb26fb46
A180: =F180&"x"&W180&"x"&S180 -> BR04xBR02xBR31 | B180: =F180&"x"&W180&"x"&S180&Q180 -> BR04xBR02xBR31Pallets: 28 | C180: EMPURRADA_1_9_2026 | D180: 07526557001505_CERV | E180: CAMAÇARI | F180: BR04 | I180: Geo NE | J180: 20618821000799 | K180: OPERALOG | L180: 390268 | N180: 1 | Q180: Pallets: 28 | R180: Unidade: CERVEJARIA PERNAMBUCO | Região: NE | S180: BR31 | T180: 950 | U180: FALSE | V180: Unidade: CERVEJARIA ESTÂNCIA | Região: NE | W180: BR02 | X180: 205 | Y180: 12500 | Z180: 1135.4 | AA180: 1507.48 | AB180: 1440 | AC180: 36000 | AD180: CERVEJARIA ESTÂNCIA_CERVEJARIA PERNAMBUCO_28_false | AG180: 1.92 | AH180: 115.5 | AI180: 0 | AJ180: 25 | AK180: 3.53 | AL180: 1.92 | AM180: 3 | AN180: 2.88 | AO180: FALSE | AP180: 8656.04 | AQ180: 10839.02 | AR180: 8559.58 | AS180: 8656.04 | AT180: 9538.34 | AU180: 3.53 | AV180: 0.01 | AW180: 0.29 | AX180: 0.1 | AY180: 0.31 | AZ180: 0 | BA180: 0.39 | BB180: 0.49 | BC180: 0 | BD180: 3581.47 | BE180: 7.75 | BF180: 299.22 | BG180: 101.36 | BH180: 309.82 | BI180: 3404.56 | BJ180: 393.96 | BK180: 461.44 | BL180: 0 | BM180: FALSE | BN180: 1440 | BO180: 12 | BP180: 1319.02 | BQ180: 507.7 | BR180: 1015.4 | BS180: 28170.78 | BT180: 21217.59 | BU180: 507.7 | BV180: 0.01 | BW180: 0.29 | BX180: 0.31 | BY180: 0.1 | CA180: 0 | CB180: 0 | CC180: 0 | CD180: 12 | CE180: 0 | CF180: 0 | CG180: 0 | CH180: 0.39 | CI180: 28.22 | CJ180: 0 | CK180: 437.68 | CL180: 1907.11 | CM180: 202400 | CN180: 3 | CO180: 28170.78 | CP180: 4611.33 | CQ180: 0.49 | CR180: 1.11 | CS180: Região: NE | CT180: 0 | CU180: 0 | CV180: 60 | CW180: 339.28 | CX180: 60 | CY180: 152.8 | CZ180: 60 | DA180: 1015.4 | DB180: TRUE | DC180: FALSE | DD180: Cargo: MODELO EQUIPE ATIVA ATUAL | DE180: 3 | DF180: 60 | DG180: 202400 | DH180: db540a9d-a77e-4710-9ebb-a080e187589f
A181: =F181&"x"&W181&"x"&S181 -> BR04xBR29xBR5D | B181: =F181&"x"&W181&"x"&S181&Q181 -> BR04xBR29xBR5DPallets: 28 | C181: EMPURRADA_1_9_2026 | D181: 07526557001505_CERV | E181: CAMAÇARI | F181: BR04 | I181: Geo NE | J181: 20618821000799 | K181: OPERALOG | L181: 390268 | N181: 1 | Q181: Pallets: 28 | R181: Unidade: CDR BAHIA | Região: NE | S181: BR5D | T181: 505 | U181: FALSE | V181: Unidade: CERVEJARIA NOVA MINAS | Região: MG | W181: BR29 | X181: 803 | Y181: 12500 | Z181: 2840.9 | AA181: 3016.03 | AB181: 1440 | AC181: 36000 | AD181: CERVEJARIA NOVA MINAS_CDR BAHIA_28_false | AG181: 1.92 | AH181: 115.5 | AI181: 0 | AJ181: 25 | AK181: 3.53 | AL181: 1.92 | AM181: 3 | AN181: 2.88 | AO181: FALSE | AP181: 16787.98 | AQ181: 21021.77 | AR181: 16600.9 | AS181: 16787.98 | AT181: 18499.16 | AU181: 3.53 | AV181: 0.01 | AW181: 0.22 | AX181: 0.1 | AY181: 0.31 | AZ181: 0 | BA181: 0.39 | BB181: 0.46 | BC181: 0 | BD181: 9597.03 | BE181: 19.39 | BF181: 598.66 | BG181: 271.61 | BH181: 830.2 | BI181: 3073.78 | BJ181: 1055.66 | BK181: 1154.57 | BL181: 0 | BM181: FALSE | BN181: 1440 | BO181: 12 | BP181: 2558.17 | BQ181: 1361.9 | BR181: 2720.9 | BS181: 30169.44 | BT181: 28417.61 | BU181: 1359 | BV181: 0.01 | BW181: 0.22 | BX181: 0.31 | BY181: 0.1 | CA181: 0 | CB181: 0 | CC181: 0 | CD181: 12 | CE181: 0 | CF181: 0 | CG181: 0 | CH181: 0.39 | CI181: 28.22 | CJ181: 0 | CK181: 437.68 | CL181: 1907.11 | CM181: 202400 | CN181: 3 | CO181: 30169.44 | CP181: 4611.33 | CQ181: 0.46 | CR181: 0.44 | CS181: Região: NE | CT181: 0 | CU181: 0 | CV181: 60 | CW181: 183.71 | CX181: 60 | CY181: 111.42 | CZ181: 60 | DA181: 2720.9 | DB181: TRUE | DC181: FALSE | DD181: Cargo: MODELO EQUIPE ATIVA ATUAL | DE181: 3 | DF181: 60 | DG181: 202400 | DH181: bcf1c62e-dfc8-4ed4-8a89-11e6013f7d60
A182: =F182&"x"&W182&"x"&S182 -> BR04xBR23xBR5D | B182: =F182&"x"&W182&"x"&S182&Q182 -> BR04xBR23xBR5DPallets: 28 | C182: EMPURRADA_1_9_2026 | D182: 07526557001505_CERV | E182: CAMAÇARI | F182: BR04 | I182: Geo NE | J182: 20618821000799 | K182: OPERALOG | L182: 390268 | N182: 1 | Q182: Pallets: 28 | R182: Unidade: CDR BAHIA | Região: NE | S182: BR5D | T182: 505 | U182: FALSE | V182: Unidade: CERVEJARIA JAGUARIÚNA | Região: SP INTERIOR | W182: BR23 | X182: 952 | Y182: 12500 | Z182: 4012.3 | AA182: 4281.21 | AB182: 1440 | AC182: 36000 | AD182: CERVEJARIA JAGUARIÚNA_CDR BAHIA_28_false | AG182: 1.92 | AH182: 115.5 | AI182: 0 | AJ182: 25 | AK182: 3.53 | AL182: 1.92 | AM182: 3 | AN182: 2.88 | AO182: FALSE | AP182: 24007.35 | AQ182: 30061.8 | AR182: 23739.81 | AS182: 24007.35 | AT182: 26454.38 | AU182: 3.53 | AV182: 0.01 | AW182: 0.22 | AX182: 0.1 | AY182: 0.31 | AZ182: 0 | BA182: 0.39 | BB182: 0.45 | BC182: 0 | BD182: 13728.74 | BE182: 27.39 | BF182: 849.78 | BG182: 388.55 | BH182: 1187.61 | BI182: 4416.96 | BJ182: 1510.14 | BK182: 1630.64 | BL182: 0 | BM182: FALSE | BN182: 1440 | BO182: 12 | BP182: 3658.26 | BQ182: 1927.4 | BR182: 3892.3 | BS182: 30557.9 | BT182: 28638.5 | BU182: 1964.9 | BV182: 0.01 | BW182: 0.22 | BX182: 0.31 | BY182: 0.1 | CA182: 0 | CB182: 0 | CC182: 0 | CD182: 12 | CE182: 0 | CF182: 0 | CG182: 0 | CH182: 0.39 | CI182: 28.22 | CJ182: 0 | CK182: 437.68 | CL182: 1907.11 | CM182: 202400 | CN182: 3 | CO182: 30557.9 | CP182: 4611.33 | CQ182: 0.45 | CR182: 0.31 | CS182: Região: NE | CT182: 0 | CU182: 0 | CV182: 60 | CW182: 183.71 | CX182: 60 | CY182: 205.2 | CZ182: 60 | DA182: 3892.3 | DB182: TRUE | DC182: FALSE | DD182: Cargo: MODELO EQUIPE ATIVA ATUAL | DE182: 3 | DF182: 60 | DG182: 202400 | DH182: d4efb2e6-425e-4926-ade6-65c694927da9
A183: =F183&"x"&W183&"x"&S183 -> BR04xBR40xBR51 | B183: =F183&"x"&W183&"x"&S183&Q183 -> BR04xBR40xBR51Pallets: 28 | C183: EMPURRADA_1_9_2026 | D183: 07526557001505_CERV | E183: CAMAÇARI | F183: BR04 | I183: Geo NE | J183: 20618821000799 | K183: OPERALOG | L183: 390268 | N183: 1 | Q183: Pallets: 28 | R183: Unidade: C. Macacu | Região: RJ INTERIOR | S183: BR51 | T183: 320 | U183: FALSE | V183: Unidade: CERVEJARIA PIRAÍ | Região: RJ CAPITAL | W183: BR40 | X183: 781 | Y183: 12500 | Z183: 427.8 | AA183: 612.22 | AB183: 1440 | AC183: 36000 | AD183: CERVEJARIA PIRAÍ_C. Macacu_28_false | AG183: 1.92 | AH183: 115.5 | AI183: 0 | AJ183: 25 | AK183: 3.53 | AL183: 1.92 | AM183: 3 | AN183: 2.88 | AO183: FALSE | AP183: 2072.74 | AQ183: 2404.22 | AR183: 2051.32 | AS183: 2072.74 | AT183: 2284.01 | AU183: 3.53 | AV183: 0.01 | AW183: 0.39 | AX183: 0.1 | AY183: 0.31 | AZ183: 0 | BA183: 0.39 | BB183: 0.61 | BC183: 0 | BD183: 1085.66 | BE183: 2.92 | BF183: 121.52 | BG183: 30.73 | BH183: 93.92 | BI183: 423.3 | BJ183: 119.42 | BK183: 173.86 | BL183: 0 | BM183: TRUE | BN183: 1440 | BO183: 5 | BP183: 120.86 | BQ183: 153.9 | BR183: 307.8 | BS183: 22664.1 | BT183: 15836.95 | BU183: 153.9 | BV183: 0.01 | BW183: 0.39 | BX183: 0.31 | BY183: 0.1 | CA183: 0 | CB183: 0 | CC183: 0 | CD183: 5 | CE183: 0 | CF183: 0 | CG183: 0 | CH183: 0.39 | CI183: 28.22 | CJ183: 0 | CK183: 437.68 | CL183: 1907.11 | CM183: 202400 | CN183: 3 | CO183: 22664.1 | CP183: 4611.33 | CQ183: 0.61 | CR183: 2.95 | CS183: Região: NE | CT183: 0 | CU183: 0 | CV183: 60 | CW183: 188.99 | CX183: 60 | CY183: 115.43 | CZ183: 60 | DA183: 307.8 | DB183: TRUE | DC183: FALSE | DD183: Cargo: MODELO EQUIPE ATIVA ATUAL | DE183: 3 | DF183: 60 | DG183: 202400 | DH183: b31699ee-6bac-45ea-b0ff-746554ebc414
A184: =F184&"x"&W184&"x"&S184 -> BR04xBR04x966673.0 | B184: =F184&"x"&W184&"x"&S184&Q184 -> BR04xBR04x966673.0Pallets: 28 | C184: EMPURRADA_1_9_2026 | D184: 07526557001505_CERV | E184: CAMAÇARI | F184: BR04 | I184: Geo NE | J184: 20618821000799 | K184: OPERALOG | L184: 390268 | N184: 1 | Q184: Pallets: 28 | R184: Unidade: 966673-ASA BRANCA/TERESINA | Região: null | S184: 966673.0 | T184: Revenda | U184: FALSE | V184: Unidade: CERVEJARIA CAMAÇARI | Região: NE | W184: BR04 | X184: 421 | Y184: 12500 | Z184: 3299.59 | AA184: 3420.89 | AB184: 1440 | AC184: 36000 | AD184: CERVEJARIA CAMAÇARI_966673-ASA BRANCA/TERESINA _28_false | AE184: 0 | AF184: 0 | AG184: 1.92 | AH184: 115.5 | AI184: 0 | AJ184: 25 | AK184: 3.53 | AL184: 1.92 | AM184: 3 | AN184: 2.88 | AO184: FALSE | AP184: 16916.77 | AQ184: 21183.03 | AR184: 16728.24 | AS184: 16916.77 | AT184: 18641.07 | AU184: 3.53 | AV184: 0.01 | AW184: 0.3 | AX184: 0.1 | AY184: 0.31 | AZ184: 0 | BA184: 0.39 | BB184: 0.64 | BC184: 0 | BD184: 8024.28 | BE184: 22.52 | BF184: 679.02 | BG184: 227.1 | BH184: 694.14 | BI184: 4767.87 | BJ184: 882.66 | BK184: 1430.66 | BL184: 0 | BM184: FALSE | BN184: 1440 | BO184: 12 | BP184: 2577.79 | BQ184: 1136 | BR184: 2275 | BS184: 21718.58 | BT184: 20948.47 | BU184: 1139 | BV184: 0.01 | BW184: 0.3 | BX184: 0.31 | BY184: 0.1 | CA184: 0 | CB184: 0 | CC184: 0 | CD184: 12 | CE184: 0 | CF184: 0 | CG184: 0 | CH184: 0.39 | CI184: 28.22 | CJ184: 0 | CK184: 437.68 | CL184: 1907.11 | CM184: 202400 | CN184: 3 | CO184: 21718.58 | CP184: 4611.33 | CQ184: 0.64 | CR184: 0.38 | CS184: Região: NE | CT184: 0 | CU184: 0 | CV184: 60 | CW184: 60 | CX184: 60 | CY184: 181.3 | CZ184: 60 | DA184: 3179.59 | DB184: TRUE | DC184: FALSE | DD184: Cargo: MODELO EQUIPE ATIVA ATUAL | DE184: 3 | DF184: 42.93 | DG184: 202400 | DH184: 1bc14d41-20c7-413a-a089-4edac99ad4a8
A185: =F185&"x"&W185&"x"&S185 -> BR04xBR5WxBR20 | B185: =F185&"x"&W185&"x"&S185&Q185 -> BR04xBR5WxBR20Pallets: 28 | C185: EMPURRADA_1_9_2026 | D185: 07526557001505_CERV | E185: CAMAÇARI | F185: BR04 | I185: Geo NE | J185: 20618821000799 | K185: OPERALOG | L185: 390268 | N185: 1 | Q185: Pallets: 28 | R185: Unidade: CERVEJARIA SAPUCAIA | Região: RS | S185: BR20 | T185: 47 | U185: FALSE | V185: Unidade: CDR EXTREMA | Região: MG | W185: BR5W | X185: 324 | Y185: 12500 | Z185: 2633.15 | AA185: 2730.67 | AB185: 1440 | AC185: 36000 | AD185: CDR EXTREMA_CERVEJARIA SAPUCAIA_28_false | AG185: 1.92 | AH185: 115.5 | AI185: 0 | AJ185: 25 | AK185: 3.53 | AL185: 1.92 | AM185: 3 | AN185: 2.88 | AO185: FALSE | AP185: 14736.78 | AQ185: 18453.27 | AR185: 14572.55 | AS185: 14736.78 | AT185: 16238.87 | AU185: 3.53 | AV185: 0.01 | AW185: 0.22 | AX185: 0.1 | AY185: 0.31 | AZ185: 0 | BA185: 0.39 | BB185: 0.46 | BC185: 0 | BD185: 8864.27 | BE185: 17.97 | BF185: 542.01 | BG185: 250.88 | BH185: 766.81 | BI185: 2085.42 | BJ185: 975.06 | BK185: 1070.14 | BL185: 0 | BM185: FALSE | BN185: 1440 | BO185: 12 | BP185: 2245.6 | BQ185: 1260.15 | BR185: 2513.15 | BS185: 30064.46 | BT185: 28990.77 | BU185: 1253 | BV185: 0.01 | BW185: 0.22 | BX185: 0.31 | BY185: 0.1 | CA185: 0 | CB185: 0 | CC185: 0 | CD185: 12 | CE185: 0 | CF185: 0 | CG185: 0 | CH185: 0.39 | CI185: 28.22 | CJ185: 0 | CK185: 437.68 | CL185: 1907.11 | CM185: 202400 | CN185: 3 | CO185: 30064.46 | CP185: 4611.33 | CQ185: 0.46 | CR185: 0.48 | CS185: Região: NE | CT185: 0 | CU185: 0 | CV185: 60 | CW185: 97.42 | CX185: 60 | CY185: 120.1 | CZ185: 60 | DA185: 2513.15 | DB185: TRUE | DC185: FALSE | DD185: Cargo: MODELO EQUIPE ATIVA ATUAL | DE185: 3 | DF185: 60 | DG185: 202400 | DH185: 342fc83f-2bd2-401a-a6ca-e00d7f46f5fa
A186: =F186&"x"&W186&"x"&S186 -> BR04xBR04x798479.0 | B186: =F186&"x"&W186&"x"&S186&Q186 -> BR04xBR04x798479.0Pallets: 28 | C186: EMPURRADA_1_9_2026 | D186: 07526557001505_CERV | E186: CAMAÇARI | F186: BR04 | I186: Geo NE | J186: 20618821000799 | K186: OPERALOG | L186: 390268 | N186: 1 | Q186: Pallets: 28 | R186: Unidade: 798479-DISCAR DISTRIBUIDORA/PRESI. DUTRA(MA) | S186: 798479.0 | T186: Revenda | U186: FALSE | V186: Unidade: CERVEJARIA CAMAÇARI | Região: NE | W186: BR04 | X186: 421 | Y186: 12500 | Z186: 2806.13 | AA186: 2927.43 | AB186: 1440 | AC186: 36000 | AD186: CERVEJARIA CAMAÇARI_798479-DISCAR DISTRIBUIDORA/PRESI. DUTRA(MA)_28_false | AE186: 0 | AF186: 0 | AG186: 1.92 | AH186: 115.5 | AI186: 0 | AJ186: 25 | AK186: 3.53 | AL186: 1.92 | AM186: 3 | AN186: 2.88 | AO186: FALSE | AP186: 20209.64 | AQ186: 25306.33 | AR186: 19984.42 | AS186: 20209.64 | AT186: 22269.57 | AU186: 3.53 | AV186: 0.01 | AW186: 0.22 | AX186: 0.1 | AY186: 0.31 | AZ186: 0 | BA186: 0.39 | BB186: 0.46 | BC186: 0 | BD186: 9474.39 | BE186: 19.15 | BF186: 581.07 | BG186: 268.14 | BH186: 819.59 | BI186: 6563.2 | BJ186: 1042.17 | BK186: 1216.7 | BL186: 0 | BM186: FALSE | BN186: 1440 | BO186: 12 | BP186: 3079.56 | BQ186: 1305.63 | BR186: 2686.13 | BS186: 30152.95 | BT186: 28903.54 | BU186: 1380.5 | BV186: 0.01 | BW186: 0.22 | BX186: 0.31 | BY186: 0.1 | CA186: 0 | CB186: 0 | CC186: 0 | CD186: 12 | CE186: 0 | CF186: 0 | CG186: 0 | CH186: 0.39 | CI186: 28.22 | CJ186: 0 | CK186: 437.68 | CL186: 1907.11 | CM186: 202400 | CN186: 3 | CO186: 30152.95 | CP186: 4611.33 | CQ186: 0.46 | CR186: 0.45 | CS186: Região: NE | CT186: 0 | CU186: 0 | CV186: 60 | CW186: 60 | CX186: 60 | CY186: 181.3 | CZ186: 60 | DA186: 2686.13 | DB186: TRUE | DC186: FALSE | DD186: Cargo: MODELO EQUIPE ATIVA ATUAL | DE186: 3 | DF186: 60 | DG186: 202400 | DH186: d6b8521e-e33f-4026-9209-b1603af0ed19
A187: =F187&"x"&W187&"x"&S187 -> BR04xBR04x820288.0 | B187: =F187&"x"&W187&"x"&S187&Q187 -> BR04xBR04x820288.0Pallets: 28 | C187: EMPURRADA_1_9_2026 | D187: 07526557001505_CERV | E187: CAMAÇARI | F187: BR04 | I187: Geo NE | J187: 20618821000799 | K187: OPERALOG | L187: 390268 | N187: 1 | Q187: Pallets: 28 | R187: Unidade: 820288-PAU BRASIL/ FILIAL ITAPORANGA | S187: 820288.0 | T187: Revenda | U187: FALSE | V187: Unidade: CERVEJARIA CAMAÇARI | Região: NE | W187: BR04 | X187: 421 | Y187: 12500 | Z187: 1598.61 | AA187: 1719.91 | AB187: 1440 | AC187: 36000 | AD187: CERVEJARIA CAMAÇARI_820288-PAU BRASIL/ FILIAL ITAPORANGA_28_false | AG187: 1.77 | AH187: 115.5 | AI187: 0 | AJ187: 25 | AK187: 3.83 | AL187: 1.77 | AM187: 3 | AN187: 2.88 | AO187: FALSE | AP187: 11494.41 | AQ187: 13619.38 | AR187: 11373.13 | AS187: 11494.41 | AT187: 12666.02 | AU187: 3.83 | AV187: 0.01 | AW187: 0.23 | AX187: 0.1 | AY187: 0.31 | AZ187: 0 | BA187: 0.39 | BB187: 0.47 | BC187: 0 | BD187: 5668.79 | BE187: 10.91 | BF187: 341.39 | BG187: 147.6 | BH187: 451.15 | BI187: 3486.49 | BJ187: 573.67 | BK187: 693.13 | BL187: 0 | BM187: FALSE | BN187: 1440 | BO187: 7 | BP187: 960.73 | BQ187: 738 | BR187: 1478.61 | BS187: 29135.45 | BT187: 27080.61 | BU187: 740.61 | BV187: 0.01 | BW187: 0.23 | BX187: 0.31 | BY187: 0.1 | CA187: 0 | CB187: 0 | CC187: 0 | CD187: 7 | CE187: 0 | CF187: 0 | CG187: -8 | CH187: 0.39 | CI187: 28.22 | CJ187: 0 | CK187: 437.68 | CL187: 1907.11 | CM187: 202400 | CN187: 3 | CO187: 29135.45 | CP187: 4611.33 | CQ187: 0.47 | CR187: 0.79 | CS187: Região: NE | CT187: 0 | CU187: 0 | CV187: 60 | CW187: 60 | CX187: 60 | CY187: 181.3 | CZ187: 60 | DA187: 1478.61 | DB187: TRUE | DC187: FALSE | DD187: Cargo: MODELO EQUIPE ATIVA ATUAL | DE187: 3 | DF187: 60 | DG187: 202400 | DH187: 824caeea-22f7-49fc-b86d-d1382e485ee6
A188: =F188&"x"&W188&"x"&S188 -> BR04xBR04x729817.0 | B188: =F188&"x"&W188&"x"&S188&Q188 -> BR04xBR04x729817.0Pallets: 28 | C188: EMPURRADA_1_9_2026 | D188: 07526557001505_CERV | E188: CAMAÇARI | F188: BR04 | I188: Geo NE | J188: 20618821000799 | K188: OPERALOG | L188: 390268 | N188: 1 | Q188: Pallets: 28 | R188: Unidade: 729817-DISBECOL/PAU DOS FERROS(RN) | S188: 729817.0 | T188: Revenda | U188: FALSE | V188: Unidade: CERVEJARIA CAMAÇARI | Região: NE | W188: BR04 | X188: 421 | Y188: 12500 | Z188: 1860.94 | AA188: 1982.24 | AB188: 1440 | AC188: 36000 | AD188: CERVEJARIA CAMAÇARI_729817-DISBECOL/PAU DOS FERROS(RN)_28_false | AG188: 1.77 | AH188: 115.5 | AI188: 0 | AJ188: 25 | AK188: 3.83 | AL188: 1.77 | AM188: 3 | AN188: 2.88 | AO188: FALSE | AP188: 13285.65 | AQ188: 16636.18 | AR188: 13137.59 | AS188: 13285.65 | AT188: 14639.83 | AU188: 3.83 | AV188: 0.01 | AW188: 0.23 | AX188: 0.1 | AY188: 0.31 | AZ188: 0 | BA188: 0.39 | BB188: 0.47 | BC188: 0 | BD188: 6674.53 | BE188: 12.7 | BF188: 393.46 | BG188: 173.79 | BH188: 531.19 | BI188: 3869.59 | BJ188: 675.45 | BK188: 806.88 | BL188: 0 | BM188: FALSE | BN188: 1440 | BO188: 12 | BP188: 2024.48 | BQ188: 869 | BR188: 1740.94 | BS188: 29468.77 | BT188: 27665.47 | BU188: 871.94 | BV188: 0.01 | BW188: 0.23 | BX188: 0.31 | BY188: 0.1 | CA188: 0 | CB188: 0 | CC188: 0 | CD188: 12 | CE188: 0 | CF188: 0 | CG188: -8 | CH188: 0.39 | CI188: 28.22 | CJ188: 0 | CK188: 437.68 | CL188: 1907.11 | CM188: 202400 | CN188: 3 | CO188: 29468.77 | CP188: 4611.33 | CQ188: 0.47 | CR188: 0.68 | CS188: Região: NE | CT188: 0 | CU188: 0 | CV188: 60 | CW188: 60 | CX188: 60 | CY188: 181.3 | CZ188: 60 | DA188: 1740.94 | DB188: TRUE | DC188: FALSE | DD188: Cargo: MODELO EQUIPE ATIVA ATUAL | DE188: 3 | DF188: 60 | DG188: 202400 | DH188: a3dad4dc-919a-4559-a79e-47fca09bdfde
A189: =F189&"x"&W189&"x"&S189 -> BR04xBR04x983610.0 | B189: =F189&"x"&W189&"x"&S189&Q189 -> BR04xBR04x983610.0Pallets: 28 | C189: EMPURRADA_1_9_2026 | D189: 07526557001505_CERV | E189: CAMAÇARI | F189: BR04 | I189: Geo NE | J189: 20618821000799 | K189: OPERALOG | L189: 390268 | N189: 1 | Q189: Pallets: 28 | R189: Unidade: 983610-REVALLE PAULO AFONSO(BA) | Região: null | S189: 983610.0 | T189: Revenda | U189: FALSE | V189: Unidade: CERVEJARIA CAMAÇARI | Região: NE | W189: BR04 | X189: 421 | Y189: 12500 | Z189: 946 | AA189: 1067.3 | AB189: 1440 | AC189: 36000 | AD189: CERVEJARIA CAMAÇARI_983610-REVALLE PAULO AFONSO(BA)_28_false | AG189: 1.77 | AH189: 115.5 | AI189: 0 | AJ189: 25 | AK189: 3.83 | AL189: 1.77 | AM189: 3 | AN189: 2.88 | AO189: FALSE | AP189: 7027.08 | AQ189: 9443.1 | AR189: 6943.11 | AS189: 7027.08 | AT189: 7743.34 | AU189: 3.83 | AV189: 0.01 | AW189: 0.23 | AX189: 0.1 | AY189: 0.31 | AZ189: 0 | BA189: 0.39 | BB189: 0.5 | BC189: 0 | BD189: 3166.77 | BE189: 6.46 | BF189: 187.77 | BG189: 82.46 | BH189: 252.03 | BI189: 2516.99 | BJ189: 320.47 | BK189: 410.17 | BL189: 0 | BM189: FALSE | BN189: 1440 | BO189: 18 | BP189: 1738.66 | BQ189: 413 | BR189: 826 | BS189: 27504.23 | BT189: 24378.34 | BU189: 413 | BV189: 0.01 | BW189: 0.23 | BX189: 0.31 | BY189: 0.1 | CA189: 0 | CB189: 0 | CC189: 0 | CD189: 18 | CE189: 0 | CF189: 0 | CG189: -8 | CH189: 0.39 | CI189: 28.22 | CJ189: 0 | CK189: 437.68 | CL189: 1907.11 | CM189: 202400 | CN189: 3 | CO189: 27504.23 | CP189: 4611.33 | CQ189: 0.5 | CR189: 1.33 | CS189: Região: NE | CT189: 0 | CU189: 0 | CV189: 60 | CW189: 60 | CX189: 60 | CY189: 181.3 | CZ189: 60 | DA189: 826 | DB189: TRUE | DC189: FALSE | DD189: Cargo: MODELO EQUIPE ATIVA ATUAL | DE189: 3 | DF189: 60 | DG189: 202400 | DH189: 44d0114b-5b6a-4efe-b777-132296d6791d
A190: =F190&"x"&W190&"x"&S190 -> BR04xBR08xBR5D | B190: =F190&"x"&W190&"x"&S190&Q190 -> BR04xBR08xBR5DPallets: 28 | C190: EMPURRADA_1_9_2026 | D190: 07526557001505_CERV | E190: CAMAÇARI | F190: BR04 | I190: Geo NE | J190: 20618821000799 | K190: OPERALOG | L190: 390268 | N190: 1 | Q190: Pallets: 28 | R190: Unidade: CDR BAHIA | Região: NE | S190: BR5D | T190: 505 | U190: FALSE | V190: Unidade: CERVEJARIA TERESINA | Região: NE | W190: BR08 | X190: 428 | Y190: 12500 | Z190: 2531.3 | AA190: 2719.77 | AB190: 1440 | AC190: 36000 | AD190: CERVEJARIA TERESINA_CDR BAHIA_28_false | AG190: 1.77 | AH190: 115.5 | AI190: 0 | AJ190: 25 | AK190: 3.83 | AL190: 1.77 | AM190: 3 | AN190: 2.88 | AO190: FALSE | AP190: 14616.97 | AQ190: 18303.24 | AR190: 14454.08 | AS190: 14616.97 | AT190: 16106.85 | AU190: 3.83 | AV190: 0.01 | AW190: 0.21 | AX190: 0.1 | AY190: 0.31 | AZ190: 0 | BA190: 0.39 | BB190: 0.46 | BC190: 0 | BD190: 9244.59 | BE190: 17.28 | BF190: 502.44 | BG190: 240.71 | BH190: 735.73 | BI190: 1801.5 | BJ190: 935.54 | BK190: 976.29 | BL190: 0 | BM190: FALSE | BN190: 1440 | BO190: 12 | BP190: 2227.35 | BQ190: 1205 | BR190: 2411.3 | BS190: 30006.7 | BT190: 27927.34 | BU190: 1206.3 | BV190: 0.01 | BW190: 0.21 | BX190: 0.31 | BY190: 0.1 | CA190: 0 | CB190: 0 | CC190: 0 | CD190: 12 | CE190: 0 | CF190: 0 | CG190: -8 | CH190: 0.39 | CI190: 28.22 | CJ190: 0 | CK190: 437.68 | CL190: 1907.11 | CM190: 202400 | CN190: 3 | CO190: 30006.7 | CP190: 4611.33 | CQ190: 0.46 | CR190: 0.5 | CS190: Região: NE | CT190: 0 | CU190: 0 | CV190: 60 | CW190: 183.71 | CX190: 60 | CY190: 124.76 | CZ190: 60 | DA190: 2411.3 | DB190: TRUE | DC190: FALSE | DD190: Cargo: MODELO EQUIPE ATIVA ATUAL | DE190: 3 | DF190: 60 | DG190: 202400 | DH190: 10593576-c8cf-4762-98c5-ba46413eb8c7
A191: =F191&"x"&W191&"x"&S191 -> BR04xBR04x101662.0 | B191: =F191&"x"&W191&"x"&S191&Q191 -> BR04xBR04x101662.0Pallets: 28 | C191: EMPURRADA_1_9_2026 | D191: 07526557001505_CERV | E191: CAMAÇARI | F191: BR04 | I191: Geo NE | J191: 20618821000799 | K191: OPERALOG | L191: 390268 | N191: 1 | Q191: Pallets: 28 | R191: Unidade: 101662-JODIBE/GARANHUNS (PE) | S191: 101662.0 | T191: Revenda | U191: FALSE | V191: Unidade: CERVEJARIA CAMAÇARI | Região: NE | W191: BR04 | X191: 421 | Y191: 12500 | Z191: 1293.96 | AA191: 1415.26 | AB191: 1440 | AC191: 36000 | AD191: CERVEJARIA CAMAÇARI_101662-JODIBE/GARANHUNS (PE)_28_false | AG191: 1.77 | AH191: 115.5 | AI191: 0 | AJ191: 25 | AK191: 3.83 | AL191: 1.77 | AM191: 3 | AN191: 2.88 | AO191: FALSE | AP191: 9513.65 | AQ191: 11912.91 | AR191: 9407.63 | AS191: 9513.65 | AT191: 10483.36 | AU191: 3.83 | AV191: 0.01 | AW191: 0.22 | AX191: 0.1 | AY191: 0.31 | AZ191: 0 | BA191: 0.39 | BB191: 0.48 | BC191: 0 | BD191: 4500.8 | BE191: 8.83 | BF191: 256.84 | BG191: 117.19 | BH191: 358.2 | BI191: 3149.25 | BJ191: 455.47 | BK191: 561.04 | BL191: 0 | BM191: FALSE | BN191: 1440 | BO191: 12 | BP191: 1449.7 | BQ191: 595.37 | BR191: 1173.96 | BS191: 28578.74 | BT191: 26129.29 | BU191: 578.59 | BV191: 0.01 | BW191: 0.22 | BX191: 0.31 | BY191: 0.1 | CA191: 0 | CB191: 0 | CC191: 0 | CD191: 12 | CE191: 0 | CF191: 0 | CG191: -8 | CH191: 0.39 | CI191: 28.22 | CJ191: 0 | CK191: 437.68 | CL191: 1907.11 | CM191: 202400 | CN191: 3 | CO191: 28578.74 | CP191: 4611.33 | CQ191: 0.48 | CR191: 0.97 | CS191: Região: NE | CT191: 0 | CU191: 0 | CV191: 60 | CW191: 60 | CX191: 60 | CY191: 181.3 | CZ191: 60 | DA191: 1173.96 | DB191: TRUE | DC191: FALSE | DD191: Cargo: MODELO EQUIPE ATIVA ATUAL | DE191: 3 | DF191: 60 | DG191: 202400 | DH191: 3f1919f0-65ac-4517-ab52-d7e8d75227db
A192: =F192&"x"&W192&"x"&S192 -> BR04xBR04x998540.0 | B192: =F192&"x"&W192&"x"&S192&Q192 -> BR04xBR04x998540.0Pallets: 28 | C192: EMPURRADA_1_9_2026 | D192: 07526557001505_CERV | E192: CAMAÇARI | F192: BR04 | I192: Geo NE | J192: 20618821000799 | K192: OPERALOG | L192: 390268 | N192: 1 | Q192: Pallets: 28 | R192: Unidade: INOVA LOG/BACABAL (MA) | S192: 998540.0 | T192: Revenda | U192: FALSE | V192: Unidade: CERVEJARIA CAMAÇARI | Região: NE | W192: BR04 | X192: 421 | Y192: 12500 | Z192: 2918 | AA192: 3039.3 | AB192: 1440 | AC192: 36000 | AD192: CERVEJARIA CAMAÇARI_INOVA LOG/BACABAL (MA)_28_false | AG192: 1.77 | AH192: 115.5 | AI192: 0 | AJ192: 25 | AK192: 3.83 | AL192: 1.77 | AM192: 3 | AN192: 2.88 | AO192: FALSE | AP192: 20474.39 | AQ192: 25637.85 | AR192: 20246.22 | AS192: 20474.39 | AT192: 22561.31 | AU192: 3.83 | AV192: 0.01 | AW192: 0.21 | AX192: 0.1 | AY192: 0.31 | AZ192: 0 | BA192: 0.39 | BB192: 0.46 | BC192: 0 | BD192: 10727.15 | BE192: 19.92 | BF192: 579.2 | BG192: 279.31 | BH192: 853.72 | BI192: 5436.15 | BJ192: 1085.57 | BK192: 1265.2 | BL192: 0 | BM192: FALSE | BN192: 1440 | BO192: 12 | BP192: 3119.91 | BQ192: 1399 | BR192: 2798 | BS192: 30204.59 | BT192: 28999.11 | BU192: 1399 | BV192: 0.01 | BW192: 0.21 | BX192: 0.31 | BY192: 0.1 | CA192: 0 | CB192: 0 | CC192: 0 | CD192: 12 | CE192: 0 | CF192: 0 | CG192: -8 | CH192: 0.39 | CI192: 28.22 | CJ192: 0 | CK192: 437.68 | CL192: 1907.11 | CM192: 202400 | CN192: 3 | CO192: 30204.59 | CP192: 4611.33 | CQ192: 0.46 | CR192: 0.43 | CS192: Região: NE | CT192: 0 | CU192: 0 | CV192: 60 | CW192: 60 | CX192: 60 | CY192: 181.3 | CZ192: 60 | DA192: 2798 | DB192: TRUE | DC192: FALSE | DD192: Cargo: MODELO EQUIPE ATIVA ATUAL | DE192: 3 | DF192: 60 | DG192: 202400 | DH192: ef2f42b3-2e69-4fac-9098-f867ed10e206
